Workbook
Name BulanSel: PENGATURAN!$C$16
Name TahunSel: PENGATURAN!$C$17
Name UnitUsaha: PENGATURAN!$B$22:$B$28
Name KodeAkun: AKUN!$A$2:$A$200

Sheet PENGATURAN
B2: BUMDESA LANCAR JAYA
B3: Sistem laporan keuangan multi-bulan — Desa Curahdringu, Kecamatan Tongas, Kabupaten Probolinggo
B5: Badan Usaha | C5: LANCAR JAYA
B6: Desa | C6: CURAHDRINGU
B7: Kecamatan | C7: TONGAS
B8: Kabupaten | C8: PROBOLINGGO
B9: Direktur | C9: DITA TIA MUKARROMAH
B10: Bendahara | C10: ROBIATUL HUSNA
B11: Penasihat | C11: ................................
B12: Pengawas | C12: ................................
B15: KONTROL PERIODE (ubah di sini)
B16: Bulan aktif (1-12) | C16: 9
B17: Tahun aktif | C17: 2025
B18: Nama bulan | C18: =TEXT(DATE(TahunSel,BulanSel,1),"mmmm")
B19: Periode aktif | C19: =DATE(TahunSel,BulanSel,1)
B21: DAFTAR UNIT USAHA (boleh diedit) | D21: RINGKASAN BULAN AKTIF
B22: Pusat | D22: Saldo kas akhir | E22: ='ARUS KAS'!$H$15
B23: Unit Pertanian | D23: Pendapatan bulan ini | E23: ='LABA RUGI'!$C$21
B24: Unit Peternakan | D24: Beban bulan ini | E24: ='LABA RUGI'!$C$48
B25: Unit Air Bersih | D25: Surplus/(Rugi) bulan ini | E25: ='LABA RUGI'!$C$50
B26: Unit Simpan Pinjam | D26: Surplus/(Rugi) s/d bulan ini | E26: ='LABA RUGI'!$D$50
B27: Unit Sewa Aset
B28: Unit Pelayanan Jasa | D28: CEK KESEHATAN DATA
D29: Jurnal Debet = Kredit? | E29: =IF(ABS(SUM(TRANSAKSI!$H$10:$H$1000)-SUM(TRANSAKSI!$I$10:$I$1000))<1,"OK — seimbang","CEK — selisih")
D30: Neraca balance? | E30: ='POSISI KEUANGAN'!$C$35
D32: Semua laporan otomatis mengikuti Bulan/Tahun aktif dan transaksi yang diisi.

Sheet TRANSAKSI
A2: TRANSAKSI JURNAL TAHUNAN
A3: Satu baris adalah satu akun. Untuk satu transaksi, isi minimal satu baris debet dan satu baris kredit dengan tanggal, unit, serta uraian yang sama.
A9: No | B9: Tanggal | C9: Unit Usaha | D9: Jenis | E9: Kode Akun | F9: Nama Akun | G9: Uraian | H9: Debet | I9: Kredit | J9: Bulan | K9: Tahun
A10: =IF($B10="","",ROW()-9) | B10: 45901 | C10: Unit Pertanian | D10: Operasional | E10: 1.1.01.01 | F10: =IF($E10="","",IFERROR(VLOOKUP($E10,AKUN!$A$2:$B$200,2,FALSE),"Kode tidak ditemukan")) | G10: [CONTOH] Saldo awal kas usaha pertanian | H10: 97950000 | J10: =IF($B10="","",MONTH($B10)) | K10: =IF($B10="","",YEAR($B10))
A11: =IF($B11="","",ROW()-9) | B11: 45901 | C11: Unit Pertanian | D11: Operasional | E11: 3.3.01.04 | F11: =IF($E11="","",IFERROR(VLOOKUP($E11,AKUN!$A$2:$B$200,2,FALSE),"Kode tidak ditemukan")) | G11: [CONTOH] Saldo awal kas usaha pertanian | I11: 97950000 | J11: =IF($B11="","",MONTH($B11)) | K11: =IF($B11="","",YEAR($B11))
A12: =IF($B12="","",ROW()-9) | B12: 45905 | C12: Unit Pertanian | D12: Operasional | E12: 1.1.01.01 | F12: =IF($E12="","",IFERROR(VLOOKUP($E12,AKUN!$A$2:$B$200,2,FALSE),"Kode tidak ditemukan")) | G12: [CONTOH] Penjualan padi | H12: 4000000 | J12: =IF($B12="","",MONTH($B12)) | K12: =IF($B12="","",YEAR($B12))
A13: =IF($B13="","",ROW()-9) | B13: 45905 | C13: Unit Pertanian | D13: Operasional | E13: 4.1.12.02 | F13: =IF($E13="","",IFERROR(VLOOKUP($E13,AKUN!$A$2:$B$200,2,FALSE),"Kode tidak ditemukan")) | G13: [CONTOH] Penjualan padi | I13: 4000000 | J13: =IF($B13="","",MONTH($B13)) | K13: =IF($B13="","",YEAR($B13))
A14: =IF($B14="","",ROW()-9) | B14: 45910 | C14: Unit Pertanian | D14: Operasional | E14: 1.1.01.01 | F14: =IF($E14="","",IFERROR(VLOOKUP($E14,AKUN!$A$2:$B$200,2,FALSE),"Kode tidak ditemukan")) | G14: [CONTOH] Penjualan jagung | H14: 3000000 | J14: =IF($B14="","",MONTH($B14)) | K14: =IF($B14="","",YEAR($B14))
A15: =IF($B15="","",ROW()-9) | B15: 45910 | C15: Unit Pertanian | D15: Operasional | E15: 4.1.12.01 | F15: =IF($E15="","",IFERROR(VLOOKUP($E15,AKUN!$A$2:$B$200,2,FALSE),"Kode tidak ditemukan")) | G15: [CONTOH] Penjualan jagung | I15: 3000000 | J15: =IF($B15="","",MONTH($B15)) | K15: =IF($B15="","",YEAR($B15))
A16: =IF($B16="","",ROW()-9) | B16: 45919 | C16: Unit Pertanian | D16: Operasional | E16: 6.2.99.99 | F16: =IF($E16="","",IFERROR(VLOOKUP($E16,AKUN!$A$2:$B$200,2,FALSE),"Kode tidak ditemukan")) | G16: [CONTOH] Upah pemupukan 2 orang | H16: 200000 | J16: =IF($B16="","",MONTH($B16)) | K16: =IF($B16="","",YEAR($B16))
A17: =IF($B17="","",ROW()-9) | B17: 45919 | C17: Unit Pertanian | D17: Operasional | E17: 1.1.01.01 | F17: =IF($E17="","",IFERROR(VLOOKUP($E17,AKUN!$A$2:$B$200,2,FALSE),"Kode tidak ditemukan")) | G17: [CONTOH] Upah pemupukan 2 orang | I17: 200000 | J17: =IF($B17="","",MONTH($B17)) | K17: =IF($B17="","",YEAR($B17))
A18: =IF($B18="","",ROW()-9) | B18: 45919 | C18: Unit Pertanian | D18: Operasional | E18: 6.2.99.05 | F18: =IF($E18="","",IFERROR(VLOOKUP($E18,AKUN!$A$2:$B$200,2,FALSE),"Kode tidak ditemukan")) | G18: [CONTOH] Pembelian pupuk phonska 1 sak | H18: 75000 | J18: =IF($B18="","",MONTH($B18)) | K18: =IF($B18="","",YEAR($B18))
A19: =IF($B19="","",ROW()-9) | B19: 45919 | C19: Unit Pertanian | D19: Operasional | E19: 1.1.01.01 | F19: =IF($E19="","",IFERROR(VLOOKUP($E19,AKUN!$A$2:$B$200,2,FALSE),"Kode tidak ditemukan")) | G19: [CONTOH] Pembelian pupuk phonska 1 sak | I19: 75000 | J19: =IF($B19="","",MONTH($B19)) | K19: =IF($B19="","",YEAR($B19))
A20: =IF($B20="","",ROW()-9) | B20: 45922 | C20: Unit Pertanian | D20: Operasional | E20: 6.1.04.01 | F20: =IF($E20="","",IFERROR(VLOOKUP($E20,AKUN!$A$2:$B$200,2,FALSE),"Kode tidak ditemukan")) | G20: [CONTOH] Pembayaran listrik | H20: 150000 | J20: =IF($B20="","",MONTH($B20)) | K20: =IF($B20="","",YEAR($B20))
A21: =IF($B21="","",ROW()-9) | B21: 45922 | C21: Unit Pertanian | D21: Operasional | E21: 1.1.01.01 | F21: =IF($E21="","",IFERROR(VLOOKUP($E21,AKUN!$A$2:$B$200,2,FALSE),"Kode tidak ditemukan")) | G21: [CONTOH] Pembayaran listrik | I21: 150000 | J21: =IF($B21="","",MONTH($B21)) | K21: =IF($B21="","",YEAR($B21))
A22: =IF($B22="","",ROW()-9) | B22: 45930 | C22: Unit Pertanian | D22: Penyesuaian | E22: 6.2.99.02 | F22: =IF($E22="","",IFERROR(VLOOKUP($E22,AKUN!$A$2:$B$200,2,FALSE),"Kode tidak ditemukan")) | G22: [CONTOH] Penyesuaian beban sewa bulan berjalan | H22: 500000 | J22: =IF($B22="","",MONTH($B22)) | K22: =IF($B22="","",YEAR($B22))
A23: =IF($B23="","",ROW()-9) | B23: 45930 | C23: Unit Pertanian | D23: Penyesuaian | E23: 1.1.07.01 | F23: =IF($E23="","",IFERROR(VLOOKUP($E23,AKUN!$A$2:$B$200,2,FALSE),"Kode tidak ditemukan")) | G23: [CONTOH] Penyesuaian beban sewa bulan berjalan | I23: 500000 | J23: =IF($B23="","",MONTH($B23)) | K23: =IF($B23="","",YEAR($B23))
A24: =IF($B24="","",ROW()-9) | B24: 45930 | C24: Unit Pertanian | D24: Penyesuaian | E24: 6.1.07.03 | F24: =IF($E24="","",IFERROR(VLOOKUP($E24,AKUN!$A$2:$B$200,2,FALSE),"Kode tidak ditemukan")) | G24: [CONTOH] Penyusutan peralatan dan mesin | H24: 300000 | J24: =IF($B24="","",MONTH($B24)) | K24: =IF($B24="","",YEAR($B24))
A25: =IF($B25="","",ROW()-9) | B25: 45930 | C25: Unit Pertanian | D25: Penyesuaian | E25: 1.3.07.02 | F25: =IF($E25="","",IFERROR(VLOOKUP($E25,AKUN!$A$2:$B$200,2,FALSE),"Kode tidak ditemukan")) | G25: [CONTOH] Penyusutan peralatan dan mesin | I25: 300000 | J25: =IF($B25="","",MONTH($B25)) | K25: =IF($B25="","",YEAR($B25))
A26: =IF($B26="","",ROW()-9) | F26: =IF($E26="","",IFERROR(VLOOKUP($E26,AKUN!$A$2:$B$200,2,FALSE),"Kode tidak ditemukan")) | J26: =IF($B26="","",MONTH($B26)) | K26: =IF($B26="","",YEAR($B26))
A27: =IF($B27="","",ROW()-9) | F27: =IF($E27="","",IFERROR(VLOOKUP($E27,AKUN!$A$2:$B$200,2,FALSE),"Kode tidak ditemukan")) | J27: =IF($B27="","",MONTH($B27)) | K27: =IF($B27="","",YEAR($B27))
A28: =IF($B28="","",ROW()-9) | F28: =IF($E28="","",IFERROR(VLOOKUP($E28,AKUN!$A$2:$B$200,2,FALSE),"Kode tidak ditemukan")) | J28: =IF($B28="","",MONTH($B28)) | K28: =IF($B28="","",YEAR($B28))
A29: =IF($B29="","",ROW()-9) | F29: =IF($E29="","",IFERROR(VLOOKUP($E29,AKUN!$A$2:$B$200,2,FALSE),"Kode tidak ditemukan")) | J29: =IF($B29="","",MONTH($B29)) | K29: =IF($B29="","",YEAR($B29))
A30: =IF($B30="","",ROW()-9) | F30: =IF($E30="","",IFERROR(VLOOKUP($E30,AKUN!$A$2:$B$200,2,FALSE),"Kode tidak ditemukan")) | J30: =IF($B30="","",MONTH($B30)) | K30: =IF($B30="","",YEAR($B30))
A31: =IF($B31="","",ROW()-9) | F31: =IF($E31="","",IFERROR(VLOOKUP($E31,AKUN!$A$2:$B$200,2,FALSE),"Kode tidak ditemukan")) | J31: =IF($B31="","",MONTH($B31)) | K31: =IF($B31="","",YEAR($B31))
A32: =IF($B32="","",ROW()-9) | F32: =IF($E32="","",IFERROR(VLOOKUP($E32,AKUN!$A$2:$B$200,2,FALSE),"Kode tidak ditemukan")) | J32: =IF($B32="","",MONTH($B32)) | K32: =IF($B32="","",YEAR($B32))
A33: =IF($B33="","",ROW()-9) | F33: =IF($E33="","",IFERROR(VLOOKUP($E33,AKUN!$A$2:$B$200,2,FALSE),"Kode tidak ditemukan")) | J33: =IF($B33="","",MONTH($B33)) | K33: =IF($B33="","",YEAR($B33))
A34: =IF($B34="","",ROW()-9) | F34: =IF($E34="","",IFERROR(VLOOKUP($E34,AKUN!$A$2:$B$200,2,FALSE),"Kode tidak ditemukan")) | J34: =IF($B34="","",MONTH($B34)) | K34: =IF($B34="","",YEAR($B34))
A35: =IF($B35="","",ROW()-9) | F35: =IF($E35="","",IFERROR(VLOOKUP($E35,AKUN!$A$2:$B$200,2,FALSE),"Kode tidak ditemukan")) | J35: =IF($B35="","",MONTH($B35)) | K35: =IF($B35="","",YEAR($B35))
A36: =IF($B36="","",ROW()-9) | F36: =IF($E36="","",IFERROR(VLOOKUP($E36,AKUN!$A$2:$B$200,2,FALSE),"Kode tidak ditemukan")) | J36: =IF($B36="","",MONTH($B36)) | K36: =IF($B36="","",YEAR($B36))
A37: =IF($B37="","",ROW()-9) | F37: =IF($E37="","",IFERROR(VLOOKUP($E37,AKUN!$A$2:$B$200,2,FALSE),"Kode tidak ditemukan")) | J37: =IF($B37="","",MONTH($B37)) | K37: =IF($B37="","",YEAR($B37))
... A1000: =IF($B1000="","",ROW()-9) | F1000: =IF($E1000="","",IFERROR(VLOOKUP($E1000,AKUN!$A$2:$B$200,2,FALSE),"Kode tidak ditemukan")) | J1000: =IF($B1000="","",MONTH($B1000)) | K1000: =IF($B1000="","",YEAR($B1000))

Sheet BULANAN
B2: RINGKASAN BULANAN PER AKUN
B3: ="Tahun aktif: "&TahunSel
A6: KODE AKUN | B6: NAMA AKUN | C6: JENIS | D6: Jan | E6: Feb | F6: Mar | G6: Apr | H6: Mei | I6: Jun | J6: Jul | K6: Agu | L6: Sep | M6: Okt | N6: Nov | O6: Des | P6: TOTAL TAHUN
A7: PENDAPATAN
A8: 4.1.02.01 | B8: Pendapatan Pengelolaan Air Bersih | C8: Pendapatan | D8: =SUMIFS('TRANSAKSI'!$I$10:$I$1000,'TRANSAKSI'!$E$10:$E$1000,"4.1.02.01",'TRANSAKSI'!$J$10:$J$1000,1,'TRANSAKSI'!$K$10:$K$1000,TahunSel)-SUMIFS('TRANSAKSI'!$H$10:$H$1000,'TRANSAKSI'!$E$10:$E$1000,"4.1.02.01",'TRANSAKSI'!$J$10:$J$1000,1,'TRANSAKSI'!$K$10:$K$1000,TahunSel) | E8: =SUMIFS('TRANSAKSI'!$I$10:$I$1000,'TRANSAKSI'!$E$10:$E$1000,"4.1.02.01",'TRANSAKSI'!$J$10:$J$1000,2,'TRANSAKSI'!$K$10:$K$1000,TahunSel)-SUMIFS('TRANSAKSI'!$H$10:$H$1000,'TRANSAKSI'!$E$10:$E$1000,"4.1.02.01",'TRANSAKSI'!$J$10:$J$1000,2,'TRANSAKSI'!$K$10:$K$1000,TahunSel) | F8: =SUMIFS('TRANSAKSI'!$I$10:$I$1000,'TRANSAKSI'!$E$10:$E$1000,"4.1.02.01",'TRANSAKSI'!$J$10:$J$1000,3,'TRANSAKSI'!$K$10:$K$1000,TahunSel)-SUMIFS('TRANSAKSI'!$H$10:$H$1000,'TRANSAKSI'!$E$10:$E$1000,"4.1.02.01",'TRANSAKSI'!$J$10:$J$1000,3,'TRANSAKSI'!$K$10:$K$1000,TahunSel) | G8: =SUMIFS('TRANSAKSI'!$I$10:$I$1000,'TRANSAKSI'!$E$10:$E$1000,"4.1.02.01",'TRANSAKSI'!$J$10:$J$1000,4,'TRANSAKSI'!$K$10:$K$1000,TahunSel)-SUMIFS('TRANSAKSI'!$H$10:$H$1000,'TRANSAKSI'!$E$10:$E$1000,"4.1.02.01",'TRANSAKSI'!$J$10:$J$1000,4,'TRANSAKSI'!$K$10:$K$1000,TahunSel) | H8: =SUMIFS('TRANSAKSI'!$I$10:$I$1000,'TRANSAKSI'!$E$10:$E$1000,"4.1.02.01",'TRANSAKSI'!$J$10:$J$1000,5,'TRANSAKSI'!$K$10:$K$1000,TahunSel)-SUMIFS('TRANSAKSI'!$H$10:$H$1000,'TRANSAKSI'!$E$10:$E$1000,"4.1.02.01",'TRANSAKSI'!$J$10:$J$1000,5,'TRANSAKSI'!$K$10:$K$1000,TahunSel) | I8: =SUMIFS('TRANSAKSI'!$I$10:$I$1000,'TRANSAKSI'!$E$10:$E$1000,"4.1.02.01",'TRANSAKSI'!$J$10:$J$1000,6,'TRANSAKSI'!$K$10:$K$1000,TahunSel)-SUMIFS('TRANSAKSI'!$H$10:$H$1000,'TRANSAKSI'!$E$10:$E$1000,"4.1.02.01",'TRANSAKSI'!$J$10:$J$1000,6,'TRANSAKSI'!$K$10:$K$1000,TahunSel) | J8: =SUMIFS('TRANSAKSI'!$I$10:$I$1000,'TRANSAKSI'!$E$10:$E$1000,"4.1.02.01",'TRANSAKSI'!$J$10:$J$1000,7,'TRANSAKSI'!$K$10:$K$1000,TahunSel)-SUMIFS('TRANSAKSI'!$H$10:$H$1000,'TRANSAKSI'!$E$10:$E$1000,"4.1.02.01",'TRANSAKSI'!$J$10:$J$1000,7,'TRANSAKSI'!$K$10:$K$1000,TahunSel) | K8: =SUMIFS('TRANSAKSI'!$I$10:$I$1000,'TRANSAKSI'!$E$10:$E$1000,"4.1.02.01",'TRANSAKSI'!$J$10:$J$1000,8,'TRANSAKSI'!$K$10:$K$1000,TahunSel)-SUMIFS('TRANSAKSI'!$H$10:$H$1000,'TRANSAKSI'!$E$10:$E$1000,"4.1.02.01",'TRANSAKSI'!$J$10:$J$1000,8,'TRANSAKSI'!$K$10:$K$1000,TahunSel) | L8: =SUMIFS('TRANSAKSI'!$I$10:$I$1000,'TRANSAKSI'!$E$10:$E$1000,"4.1.02.01",'TRANSAKSI'!$J$10:$J$1000,9,'TRANSAKSI'!$K$10:$K$1000,TahunSel)-SUMIFS('TRANSAKSI'!$H$10:$H$1000,'TRANSAKSI'!$E$10:$E$1000,"4.1.02.01",'TRANSAKSI'!$J$10:$J$1000,9,'TRANSAKSI'!$K$10:$K$1000,TahunSel) | M8: =SUMIFS('TRANSAKSI'!$I$10:$I$1000,'TRANSAKSI'!$E$10:$E$1000,"4.1.02.01",'TRANSAKSI'!$J$10:$J$1000,10,'TRANSAKSI'!$K$10:$K$1000,TahunSel)-SUMIFS('TRANSAKSI'!$H$10:$H$1000,'TRANSAKSI'!$E$10:$E$1000,"4.1.02.01",'TRANSAKSI'!$J$10:$J$1000,10,'TRANSAKSI'!$K$10:$K$1000,TahunSel) | N8: =SUMIFS('TRANSAKSI'!$I$10:$I$1000,'TRANSAKSI'!$E$10:$E$1000,"4.1.02.01",'TRANSAKSI'!$J$10:$J$1000,11,'TRANSAKSI'!$K$10:$K$1000,TahunSel)-SUMIFS('TRANSAKSI'!$H$10:$H$1000,'TRANSAKSI'!$E$10:$E$1000,"4.1.02.01",'TRANSAKSI'!$J$10:$J$1000,11,'TRANSAKSI'!$K$10:$K$1000,TahunSel) | O8: =SUMIFS('TRANSAKSI'!$I$10:$I$1000,'TRANSAKSI'!$E$10:$E$1000,"4.1.02.01",'TRANSAKSI'!$J$10:$J$1000,12,'TRANSAKSI'!$K$10:$K$1000,TahunSel)-SUMIFS('TRANSAKSI'!$H$10:$H$1000,'TRANSAKSI'!$E$10:$E$1000,"4.1.02.01",'TRANSAKSI'!$J$10:$J$1000,12,'TRANSAKSI'!$K$10:$K$1000,TahunSel) | P8: =SUM(D8:O8)
A9: 4.1.03.01 | B9: Pendapatan Pengelolaan Sampah | C9: Pendapatan | D9: =SUMIFS('TRANSAKSI'!$I$10:$I$1000,'TRANSAKSI'!$E$10:$E$1000,"4.1.03.01",'TRANSAKSI'!$J$10:$J$1000,1,'TRANSAKSI'!$K$10:$K$1000,TahunSel)-SUMIFS('TRANSAKSI'!$H$10:$H$1000,'TRANSAKSI'!$E$10:$E$1000,"4.1.03.01",'TRANSAKSI'!$J$10:$J$1000,1,'TRANSAKSI'!$K$10:$K$1000,TahunSel) | E9: =SUMIFS('TRANSAKSI'!$I$10:$I$1000,'TRANSAKSI'!$E$10:$E$1000,"4.1.03.01",'TRANSAKSI'!$J$10:$J$1000,2,'TRANSAKSI'!$K$10:$K$1000,TahunSel)-SUMIFS('TRANSAKSI'!$H$10:$H$1000,'TRANSAKSI'!$E$10:$E$1000,"4.1.03.01",'TRANSAKSI'!$J$10:$J$1000,2,'TRANSAKSI'!$K$10:$K$1000,TahunSel) | F9: =SUMIFS('TRANSAKSI'!$I$10:$I$1000,'TRANSAKSI'!$E$10:$E$1000,"4.1.03.01",'TRANSAKSI'!$J$10:$J$1000,3,'TRANSAKSI'!$K$10:$K$1000,TahunSel)-SUMIFS('TRANSAKSI'!$H$10:$H$1000,'TRANSAKSI'!$E$10:$E$1000,"4.1.03.01",'TRANSAKSI'!$J$10:$J$1000,3,'TRANSAKSI'!$K$10:$K$1000,TahunSel) | G9: =SUMIFS('TRANSAKSI'!$I$10:$I$1000,'TRANSAKSI'!$E$10:$E$1000,"4.1.03.01",'TRANSAKSI'!$J$10:$J$1000,4,'TRANSAKSI'!$K$10:$K$1000,TahunSel)-SUMIFS('TRANSAKSI'!$H$10:$H$1000,'TRANSAKSI'!$E$10:$E$1000,"4.1.03.01",'TRANSAKSI'!$J$10:$J$1000,4,'TRANSAKSI'!$K$10:$K$1000,TahunSel) | H9: =SUMIFS('TRANSAKSI'!$I$10:$I$1000,'TRANSAKSI'!$E$10:$E$1000,"4.1.03.01",'TRANSAKSI'!$J$10:$J$1000,5,'TRANSAKSI'!$K$10:$K$1000,TahunSel)-SUMIFS('TRANSAKSI'!$H$10:$H$1000,'TRANSAKSI'!$E$10:$E$1000,"4.1.03.01",'TRANSAKSI'!$J$10:$J$1000,5,'TRANSAKSI'!$K$10:$K$1000,TahunSel) | I9: =SUMIFS('TRANSAKSI'!$I$10:$I$1000,'TRANSAKSI'!$E$10:$E$1000,"4.1.03.01",'TRANSAKSI'!$J$10:$J$1000,6,'TRANSAKSI'!$K$10:$K$1000,TahunSel)-SUMIFS('TRANSAKSI'!$H$10:$H$1000,'TRANSAKSI'!$E$10:$E$1000,"4.1.03.01",'TRANSAKSI'!$J$10:$J$1000,6,'TRANSAKSI'!$K$10:$K$1000,TahunSel) | J9: =SUMIFS('TRANSAKSI'!$I$10:$I$1000,'TRANSAKSI'!$E$10:$E$1000,"4.1.03.01",'TRANSAKSI'!$J$10:$J$1000,7,'TRANSAKSI'!$K$10:$K$1000,TahunSel)-SUMIFS('TRANSAKSI'!$H$10:$H$1000,'TRANSAKSI'!$E$10:$E$1000,"4.1.03.01",'TRANSAKSI'!$J$10:$J$1000,7,'TRANSAKSI'!$K$10:$K$1000,TahunSel) | K9: =SUMIFS('TRANSAKSI'!$I$10:$I$1000,'TRANSAKSI'!$E$10:$E$1000,"4.1.03.01",'TRANSAKSI'!$J$10:$J$1000,8,'TRANSAKSI'!$K$10:$K$1000,TahunSel)-SUMIFS('TRANSAKSI'!$H$10:$H$1000,'TRANSAKSI'!$E$10:$E$1000,"4.1.03.01",'TRANSAKSI'!$J$10:$J$1000,8,'TRANSAKSI'!$K$10:$K$1000,TahunSel) | L9: =SUMIFS('TRANSAKSI'!$I$10:$I$1000,'TRANSAKSI'!$E$10:$E$1000,"4.1.03.01",'TRANSAKSI'!$J$10:$J$1000,9,'TRANSAKSI'!$K$10:$K$1000,TahunSel)-SUMIFS('TRANSAKSI'!$H$10:$H$1000,'TRANSAKSI'!$E$10:$E$1000,"4.1.03.01",'TRANSAKSI'!$J$10:$J$1000,9,'TRANSAKSI'!$K$10:$K$1000,TahunSel) | M9: =SUMIFS('TRANSAKSI'!$I$10:$I$1000,'TRANSAKSI'!$E$10:$E$1000,"4.1.03.01",'TRANSAKSI'!$J$10:$J$1000,10,'TRANSAKSI'!$K$10:$K$1000,TahunSel)-SUMIFS('TRANSAKSI'!$H$10:$H$1000,'TRANSAKSI'!$E$10:$E$1000,"4.1.03.01",'TRANSAKSI'!$J$10:$J$1000,10,'TRANSAKSI'!$K$10:$K$1000,TahunSel) | N9: =SUMIFS('TRANSAKSI'!$I$10:$I$1000,'TRANSAKSI'!$E$10:$E$1000,"4.1.03.01",'TRANSAKSI'!$J$10:$J$1000,11,'TRANSAKSI'!$K$10:$K$1000,TahunSel)-SUMIFS('TRANSAKSI'!$H$10:$H$1000,'TRANSAKSI'!$E$10:$E$1000,"4.1.03.01",'TRANSAKSI'!$J$10:$J$1000,11,'TRANSAKSI'!$K$10:$K$1000,TahunSel) | O9: =SUMIFS('TRANSAKSI'!$I$10:$I$1000,'TRANSAKSI'!$E$10:$E$1000,"4.1.03.01",'TRANSAKSI'!$J$10:$J$1000,12,'TRANSAKSI'!$K$10:$K$1000,TahunSel)-SUMIFS('TRANSAKSI'!$H$10:$H$1000,'TRANSAKSI'!$E$10:$E$1000,"4.1.03.01",'TRANSAKSI'!$J$10:$J$1000,12,'TRANSAKSI'!$K$10:$K$1000,TahunSel) | P9: =SUM(D9:O9)
A10: 4.1.04.02 | B10: Pendapatan Sewa Toko dan Kios | C10: Pendapatan | D10: =SUMIFS('TRANSAKSI'!$I$10:$I$1000,'TRANSAKSI'!$E$10:$E$1000,"4.1.04.02",'TRANSAKSI'!$J$10:$J$1000,1,'TRANSAKSI'!$K$10:$K$1000,TahunSel)-SUMIFS('TRANSAKSI'!$H$10:$H$1000,'TRANSAKSI'!$E$10:$E$1000,"4.1.04.02",'TRANSAKSI'!$J$10:$J$1000,1,'TRANSAKSI'!$K$10:$K$1000,TahunSel) | E10: =SUMIFS('TRANSAKSI'!$I$10:$I$1000,'TRANSAKSI'!$E$10:$E$1000,"4.1.04.02",'TRANSAKSI'!$J$10:$J$1000,2,'TRANSAKSI'!$K$10:$K$1000,TahunSel)-SUMIFS('TRANSAKSI'!$H$10:$H$1000,'TRANSAKSI'!$E$10:$E$1000,"4.1.04.02",'TRANSAKSI'!$J$10:$J$1000,2,'TRANSAKSI'!$K$10:$K$1000,TahunSel) | F10: =SUMIFS('TRANSAKSI'!$I$10:$I$1000,'TRANSAKSI'!$E$10:$E$1000,"4.1.04.02",'TRANSAKSI'!$J$10:$J$1000,3,'TRANSAKSI'!$K$10:$K$1000,TahunSel)-SUMIFS('TRANSAKSI'!$H$10:$H$1000,'TRANSAKSI'!$E$10:$E$1000,"4.1.04.02",'TRANSAKSI'!$J$10:$J$1000,3,'TRANSAKSI'!$K$10:$K$1000,TahunSel) | G10: =SUMIFS('TRANSAKSI'!$I$10:$I$1000,'TRANSAKSI'!$E$10:$E$1000,"4.1.04.02",'TRANSAKSI'!$J$10:$J$1000,4,'TRANSAKSI'!$K$10:$K$1000,TahunSel)-SUMIFS('TRANSAKSI'!$H$10:$H$1000,'TRANSAKSI'!$E$10:$E$1000,"4.1.04.02",'TRANSAKSI'!$J$10:$J$1000,4,'TRANSAKSI'!$K$10:$K$1000,TahunSel) | H10: =SUMIFS('TRANSAKSI'!$I$10:$I$1000,'TRANSAKSI'!$E$10:$E$1000,"4.1.04.02",'TRANSAKSI'!$J$10:$J$1000,5,'TRANSAKSI'!$K$10:$K$1000,TahunSel)-SUMIFS('TRANSAKSI'!$H$10:$H$1000,'TRANSAKSI'!$E$10:$E$1000,"4.1.04.02",'TRANSAKSI'!$J$10:$J$1000,5,'TRANSAKSI'!$K$10:$K$1000,TahunSel) | I10: =SUMIFS('TRANSAKSI'!$I$10:$I$1000,'TRANSAKSI'!$E$10:$E$1000,"4.1.04.02",'TRANSAKSI'!$J$10:$J$1000,6,'TRANSAKSI'!$K$10:$K$1000,TahunSel)-SUMIFS('TRANSAKSI'!$H$10:$H$1000,'TRANSAKSI'!$E$10:$E$1000,"4.1.04.02",'TRANSAKSI'!$J$10:$J$1000,6,'TRANSAKSI'!$K$10:$K$1000,TahunSel) | J10: =SUMIFS('TRANSAKSI'!$I$10:$I$1000,'TRANSAKSI'!$E$10:$E$1000,"4.1.04.02",'TRANSAKSI'!$J$10:$J$1000,7,'TRANSAKSI'!$K$10:$K$1000,TahunSel)-SUMIFS('TRANSAKSI'!$H$10:$H$1000,'TRANSAKSI'!$E$10:$E$1000,"4.1.04.02",'TRANSAKSI'!$J$10:$J$1000,7,'TRANSAKSI'!$K$10:$K$1000,TahunSel) | K10: =SUMIFS('TRANSAKSI'!$I$10:$I$1000,'TRANSAKSI'!$E$10:$E$1000,"4.1.04.02",'TRANSAKSI'!$J$10:$J$1000,8,'TRANSAKSI'!$K$10:$K$1000,TahunSel)-SUMIFS('TRANSAKSI'!$H$10:$H$1000,'TRANSAKSI'!$E$10:$E$1000,"4.1.04.02",'TRANSAKSI'!$J$10:$J$1000,8,'TRANSAKSI'!$K$10:$K$1000,TahunSel) | L10: =SUMIFS('TRANSAKSI'!$I$10:$I$1000,'TRANSAKSI'!$E$10:$E$1000,"4.1.04.02",'TRANSAKSI'!$J$10:$J$1000,9,'TRANSAKSI'!$K$10:$K$1000,TahunSel)-SUMIFS('TRANSAKSI'!$H$10:$H$1000,'TRANSAKSI'!$E$10:$E$1000,"4.1.04.02",'TRANSAKSI'!$J$10:$J$1000,9,'TRANSAKSI'!$K$10:$K$1000,TahunSel) | M10: =SUMIFS('TRANSAKSI'!$I$10:$I$1000,'TRANSAKSI'!$E$10:$E$1000,"4.1.04.02",'TRANSAKSI'!$J$10:$J$1000,10,'TRANSAKSI'!$K$10:$K$1000,TahunSel)-SUMIFS('TRANSAKSI'!$H$10:$H$1000,'TRANSAKSI'!$E$10:$E$1000,"4.1.04.02",'TRANSAKSI'!$J$10:$J$1000,10,'TRANSAKSI'!$K$10:$K$1000,TahunSel) | N10: =SUMIFS('TRANSAKSI'!$I$10:$I$1000,'TRANSAKSI'!$E$10:$E$1000,"4.1.04.02",'TRANSAKSI'!$J$10:$J$1000,11,'TRANSAKSI'!$K$10:$K$1000,TahunSel)-SUMIFS('TRANSAKSI'!$H$10:$H$1000,'TRANSAKSI'!$E$10:$E$1000,"4.1.04.02",'TRANSAKSI'!$J$10:$J$1000,11,'TRANSAKSI'!$K$10:$K$1000,TahunSel) | O10: =SUMIFS('TRANSAKSI'!$I$10:$I$1000,'TRANSAKSI'!$E$10:$E$1000,"4.1.04.02",'TRANSAKSI'!$J$10:$J$1000,12,'TRANSAKSI'!$K$10:$K$1000,TahunSel)-SUMIFS('TRANSAKSI'!$H$10:$H$1000,'TRANSAKSI'!$E$10:$E$1000,"4.1.04.02",'TRANSAKSI'!$J$10:$J$1000,12,'TRANSAKSI'!$K$10:$K$1000,TahunSel) | P10: =SUM(D10:O10)
A11: 4.1.04.03 | B11: Pendapatan Sewa Gedung | C11: Pendapatan | D11: =SUMIFS('TRANSAKSI'!$I$10:$I$1000,'TRANSAKSI'!$E$10:$E$1000,"4.1.04.03",'TRANSAKSI'!$J$10:$J$1000,1,'TRANSAKSI'!$K$10:$K$1000,TahunSel)-SUMIFS('TRANSAKSI'!$H$10:$H$1000,'TRANSAKSI'!$E$10:$E$1000,"4.1.04.03",'TRANSAKSI'!$J$10:$J$1000,1,'TRANSAKSI'!$K$10:$K$1000,TahunSel) | E11: =SUMIFS('TRANSAKSI'!$I$10:$I$1000,'TRANSAKSI'!$E$10:$E$1000,"4.1.04.03",'TRANSAKSI'!$J$10:$J$1000,2,'TRANSAKSI'!$K$10:$K$1000,TahunSel)-SUMIFS('TRANSAKSI'!$H$10:$H$1000,'TRANSAKSI'!$E$10:$E$1000,"4.1.04.03",'TRANSAKSI'!$J$10:$J$1000,2,'TRANSAKSI'!$K$10:$K$1000,TahunSel) | F11: =SUMIFS('TRANSAKSI'!$I$10:$I$1000,'TRANSAKSI'!$E$10:$E$1000,"4.1.04.03",'TRANSAKSI'!$J$10:$J$1000,3,'TRANSAKSI'!$K$10:$K$1000,TahunSel)-SUMIFS('TRANSAKSI'!$H$10:$H$1000,'TRANSAKSI'!$E$10:$E$1000,"4.1.04.03",'TRANSAKSI'!$J$10:$J$1000,3,'TRANSAKSI'!$K$10:$K$1000,TahunSel) | G11: =SUMIFS('TRANSAKSI'!$I$10:$I$1000,'TRANSAKSI'!$E$10:$E$1000,"4.1.04.03",'TRANSAKSI'!$J$10:$J$1000,4,'TRANSAKSI'!$K$10:$K$1000,TahunSel)-SUMIFS('TRANSAKSI'!$H$10:$H$1000,'TRANSAKSI'!$E$10:$E$1000,"4.1.04.03",'TRANSAKSI'!$J$10:$J$1000,4,'TRANSAKSI'!$K$10:$K$1000,TahunSel) | H11: =SUMIFS('TRANSAKSI'!$I$10:$I$1000,'TRANSAKSI'!$E$10:$E$1000,"4.1.04.03",'TRANSAKSI'!$J$10:$J$1000,5,'TRANSAKSI'!$K$10:$K$1000,TahunSel)-SUMIFS('TRANSAKSI'!$H$10:$H$1000,'TRANSAKSI'!$E$10:$E$1000,"4.1.04.03",'TRANSAKSI'!$J$10:$J$1000,5,'TRANSAKSI'!$K$10:$K$1000,TahunSel) | I11: =SUMIFS('TRANSAKSI'!$I$10:$I$1000,'TRANSAKSI'!$E$10:$E$1000,"4.1.04.03",'TRANSAKSI'!$J$10:$J$1000,6,'TRANSAKSI'!$K$10:$K$1000,TahunSel)-SUMIFS('TRANSAKSI'!$H$10:$H$1000,'TRANSAKSI'!$E$10:$E$1000,"4.1.04.03",'TRANSAKSI'!$J$10:$J$1000,6,'TRANSAKSI'!$K$10:$K$1000,TahunSel) | J11: =SUMIFS('TRANSAKSI'!$I$10:$I$1000,'TRANSAKSI'!$E$10:$E$1000,"4.1.04.03",'TRANSAKSI'!$J$10:$J$1000,7,'TRANSAKSI'!$K$10:$K$1000,TahunSel)-SUMIFS('TRANSAKSI'!$H$10:$H$1000,'TRANSAKSI'!$E$10:$E$1000,"4.1.04.03",'TRANSAKSI'!$J$10:$J$1000,7,'TRANSAKSI'!$K$10:$K$1000,TahunSel) | K11: =SUMIFS('TRANSAKSI'!$I$10:$I$1000,'TRANSAKSI'!$E$10:$E$1000,"4.1.04.03",'TRANSAKSI'!$J$10:$J$1000,8,'TRANSAKSI'!$K$10:$K$1000,TahunSel)-SUMIFS('TRANSAKSI'!$H$10:$H$1000,'TRANSAKSI'!$E$10:$E$1000,"4.1.04.03",'TRANSAKSI'!$J$10:$J$1000,8,'TRANSAKSI'!$K$10:$K$1000,TahunSel) | L11: =SUMIFS('TRANSAKSI'!$I$10:$I$1000,'TRANSAKSI'!$E$10:$E$1000,"4.1.04.03",'TRANSAKSI'!$J$10:$J$1000,9,'TRANSAKSI'!$K$10:$K$1000,TahunSel)-SUMIFS('TRANSAKSI'!$H$10:$H$1000,'TRANSAKSI'!$E$10:$E$1000,"4.1.04.03",'TRANSAKSI'!$J$10:$J$1000,9,'TRANSAKSI'!$K$10:$K$1000,TahunSel) | M11: =SUMIFS('TRANSAKSI'!$I$10:$I$1000,'TRANSAKSI'!$E$10:$E$1000,"4.1.04.03",'TRANSAKSI'!$J$10:$J$1000,10,'TRANSAKSI'!$K$10:$K$1000,TahunSel)-SUMIFS('TRANSAKSI'!$H$10:$H$1000,'TRANSAKSI'!$E$10:$E$1000,"4.1.04.03",'TRANSAKSI'!$J$10:$J$1000,10,'TRANSAKSI'!$K$10:$K$1000,TahunSel) | N11: =SUMIFS('TRANSAKSI'!$I$10:$I$1000,'TRANSAKSI'!$E$10:$E$1000,"4.1.04.03",'TRANSAKSI'!$J$10:$J$1000,11,'TRANSAKSI'!$K$10:$K$1000,TahunSel)-SUMIFS('TRANSAKSI'!$H$10:$H$1000,'TRANSAKSI'!$E$10:$E$1000,"4.1.04.03",'TRANSAKSI'!$J$10:$J$1000,11,'TRANSAKSI'!$K$10:$K$1000,TahunSel) | O11: =SUMIFS('TRANSAKSI'!$I$10:$I$1000,'TRANSAKSI'!$E$10:$E$1000,"4.1.04.03",'TRANSAKSI'!$J$10:$J$1000,12,'TRANSAKSI'!$K$10:$K$1000,TahunSel)-SUMIFS('TRANSAKSI'!$H$10:$H$1000,'TRANSAKSI'!$E$10:$E$1000,"4.1.04.03",'TRANSAKSI'!$J$10:$J$1000,12,'TRANSAKSI'!$K$10:$K$1000,TahunSel) | P11: =SUM(D11:O11)
A12: 4.1.04.06 | B12: Pendapatan Sewa Jaring | C12: Pendapatan | D12: =SUMIFS('TRANSAKSI'!$I$10:$I$1000,'TRANSAKSI'!$E$10:$E$1000,"4.1.04.06",'TRANSAKSI'!$J$10:$J$1000,1,'TRANSAKSI'!$K$10:$K$1000,TahunSel)-SUMIFS('TRANSAKSI'!$H$10:$H$1000,'TRANSAKSI'!$E$10:$E$1000,"4.1.04.06",'TRANSAKSI'!$J$10:$J$1000,1,'TRANSAKSI'!$K$10:$K$1000,TahunSel) | E12: =SUMIFS('TRANSAKSI'!$I$10:$I$1000,'TRANSAKSI'!$E$10:$E$1000,"4.1.04.06",'TRANSAKSI'!$J$10:$J$1000,2,'TRANSAKSI'!$K$10:$K$1000,TahunSel)-SUMIFS('TRANSAKSI'!$H$10:$H$1000,'TRANSAKSI'!$E$10:$E$1000,"4.1.04.06",'TRANSAKSI'!$J$10:$J$1000,2,'TRANSAKSI'!$K$10:$K$1000,TahunSel) | F12: =SUMIFS('TRANSAKSI'!$I$10:$I$1000,'TRANSAKSI'!$E$10:$E$1000,"4.1.04.06",'TRANSAKSI'!$J$10:$J$1000,3,'TRANSAKSI'!$K$10:$K$1000,TahunSel)-SUMIFS('TRANSAKSI'!$H$10:$H$1000,'TRANSAKSI'!$E$10:$E$1000,"4.1.04.06",'TRANSAKSI'!$J$10:$J$1000,3,'TRANSAKSI'!$K$10:$K$1000,TahunSel) | G12: =SUMIFS('TRANSAKSI'!$I$10:$I$1000,'TRANSAKSI'!$E$10:$E$1000,"4.1.04.06",'TRANSAKSI'!$J$10:$J$1000,4,'TRANSAKSI'!$K$10:$K$1000,TahunSel)-SUMIFS('TRANSAKSI'!$H$10:$H$1000,'TRANSAKSI'!$E$10:$E$1000,"4.1.04.06",'TRANSAKSI'!$J$10:$J$1000,4,'TRANSAKSI'!$K$10:$K$1000,TahunSel) | H12: =SUMIFS('TRANSAKSI'!$I$10:$I$1000,'TRANSAKSI'!$E$10:$E$1000,"4.1.04.06",'TRANSAKSI'!$J$10:$J$1000,5,'TRANSAKSI'!$K$10:$K$1000,TahunSel)-SUMIFS('TRANSAKSI'!$H$10:$H$1000,'TRANSAKSI'!$E$10:$E$1000,"4.1.04.06",'TRANSAKSI'!$J$10:$J$1000,5,'TRANSAKSI'!$K$10:$K$1000,TahunSel) | I12: =SUMIFS('TRANSAKSI'!$I$10:$I$1000,'TRANSAKSI'!$E$10:$E$1000,"4.1.04.06",'TRANSAKSI'!$J$10:$J$1000,6,'TRANSAKSI'!$K$10:$K$1000,TahunSel)-SUMIFS('TRANSAKSI'!$H$10:$H$1000,'TRANSAKSI'!$E$10:$E$1000,"4.1.04.06",'TRANSAKSI'!$J$10:$J$1000,6,'TRANSAKSI'!$K$10:$K$1000,TahunSel) | J12: =SUMIFS('TRANSAKSI'!$I$10:$I$1000,'TRANSAKSI'!$E$10:$E$1000,"4.1.04.06",'TRANSAKSI'!$J$10:$J$1000,7,'TRANSAKSI'!$K$10:$K$1000,TahunSel)-SUMIFS('TRANSAKSI'!$H$10:$H$1000,'TRANSAKSI'!$E$10:$E$1000,"4.1.04.06",'TRANSAKSI'!$J$10:$J$1000,7,'TRANSAKSI'!$K$10:$K$1000,TahunSel) | K12: =SUMIFS('TRANSAKSI'!$I$10:$I$1000,'TRANSAKSI'!$E$10:$E$1000,"4.1.04.06",'TRANSAKSI'!$J$10:$J$1000,8,'TRANSAKSI'!$K$10:$K$1000,TahunSel)-SUMIFS('TRANSAKSI'!$H$10:$H$1000,'TRANSAKSI'!$E$10:$E$1000,"4.1.04.06",'TRANSAKSI'!$J$10:$J$1000,8,'TRANSAKSI'!$K$10:$K$1000,TahunSel) | L12: =SUMIFS('TRANSAKSI'!$I$10:$I$1000,'TRANSAKSI'!$E$10:$E$1000,"4.1.04.06",'TRANSAKSI'!$J$10:$J$1000,9,'TRANSAKSI'!$K$10:$K$1000,TahunSel)-SUMIFS('TRANSAKSI'!$H$10:$H$1000,'TRANSAKSI'!$E$10:$E$1000,"4.1.04.06",'TRANSAKSI'!$J$10:$J$1000,9,'TRANSAKSI'!$K$10:$K$1000,TahunSel) | M12: =SUMIFS('TRANSAKSI'!$I$10:$I$1000,'TRANSAKSI'!$E$10:$E$1000,"4.1.04.06",'TRANSAKSI'!$J$10:$J$1000,10,'TRANSAKSI'!$K$10:$K$1000,TahunSel)-SUMIFS('TRANSAKSI'!$H$10:$H$1000,'TRANSAKSI'!$E$10:$E$1000,"4.1.04.06",'TRANSAKSI'!$J$10:$J$1000,10,'TRANSAKSI'!$K$10:$K$1000,TahunSel) | N12: =SUMIFS('TRANSAKSI'!$I$10:$I$1000,'TRANSAKSI'!$E$10:$E$1000,"4.1.04.06",'TRANSAKSI'!$J$10:$J$1000,11,'TRANSAKSI'!$K$10:$K$1000,TahunSel)-SUMIFS('TRANSAKSI'!$H$10:$H$1000,'TRANSAKSI'!$E$10:$E$1000,"4.1.04.06",'TRANSAKSI'!$J$10:$J$1000,11,'TRANSAKSI'!$K$10:$K$1000,TahunSel) | O12: =SUMIFS('TRANSAKSI'!$I$10:$I$1000,'TRANSAKSI'!$E$10:$E$1000,"4.1.04.06",'TRANSAKSI'!$J$10:$J$1000,12,'TRANSAKSI'!$K$10:$K$1000,TahunSel)-SUMIFS('TRANSAKSI'!$H$10:$H$1000,'TRANSAKSI'!$E$10:$E$1000,"4.1.04.06",'TRANSAKSI'!$J$10:$J$1000,12,'TRANSAKSI'!$K$10:$K$1000,TahunSel) | P12: =SUM(D12:O12)
A13: 4.1.05.01 | B13: Pendapatan Jasa Bayar Listrik | C13: Pendapatan | D13: =SUMIFS('TRANSAKSI'!$I$10:$I$1000,'TRANSAKSI'!$E$10:$E$1000,"4.1.05.01",'TRANSAKSI'!$J$10:$J$1000,1,'TRANSAKSI'!$K$10:$K$1000,TahunSel)-SUMIFS('TRANSAKSI'!$H$10:$H$1000,'TRANSAKSI'!$E$10:$E$1000,"4.1.05.01",'TRANSAKSI'!$J$10:$J$1000,1,'TRANSAKSI'!$K$10:$K$1000,TahunSel) | E13: =SUMIFS('TRANSAKSI'!$I$10:$I$1000,'TRANSAKSI'!$E$10:$E$1000,"4.1.05.01",'TRANSAKSI'!$J$10:$J$1000,2,'TRANSAKSI'!$K$10:$K$1000,TahunSel)-SUMIFS('TRANSAKSI'!$H$10:$H$1000,'TRANSAKSI'!$E$10:$E$1000,"4.1.05.01",'TRANSAKSI'!$J$10:$J$1000,2,'TRANSAKSI'!$K$10:$K$1000,TahunSel) | F13: =SUMIFS('TRANSAKSI'!$I$10:$I$1000,'TRANSAKSI'!$E$10:$E$1000,"4.1.05.01",'TRANSAKSI'!$J$10:$J$1000,3,'TRANSAKSI'!$K$10:$K$1000,TahunSel)-SUMIFS('TRANSAKSI'!$H$10:$H$1000,'TRANSAKSI'!$E$10:$E$1000,"4.1.05.01",'TRANSAKSI'!$J$10:$J$1000,3,'TRANSAKSI'!$K$10:$K$1000,TahunSel) | G13: =SUMIFS('TRANSAKSI'!$I$10:$I$1000,'TRANSAKSI'!$E$10:$E$1000,"4.1.05.01",'TRANSAKSI'!$J$10:$J$1000,4,'TRANSAKSI'!$K$10:$K$1000,TahunSel)-SUMIFS('TRANSAKSI'!$H$10:$H$1000,'TRANSAKSI'!$E$10:$E$1000,"4.1.05.01",'TRANSAKSI'!$J$10:$J$1000,4,'TRANSAKSI'!$K$10:$K$1000,TahunSel) | H13: =SUMIFS('TRANSAKSI'!$I$10:$I$1000,'TRANSAKSI'!$E$10:$E$1000,"4.1.05.01",'TRANSAKSI'!$J$10:$J$1000,5,'TRANSAKSI'!$K$10:$K$1000,TahunSel)-SUMIFS('TRANSAKSI'!$H$10:$H$1000,'TRANSAKSI'!$E$10:$E$1000,"4.1.05.01",'TRANSAKSI'!$J$10:$J$1000,5,'TRANSAKSI'!$K$10:$K$1000,TahunSel) | I13: =SUMIFS('TRANSAKSI'!$I$10:$I$1000,'TRANSAKSI'!$E$10:$E$1000,"4.1.05.01",'TRANSAKSI'!$J$10:$J$1000,6,'TRANSAKSI'!$K$10:$K$1000,TahunSel)-SUMIFS('TRANSAKSI'!$H$10:$H$1000,'TRANSAKSI'!$E$10:$E$1000,"4.1.05.01",'TRANSAKSI'!$J$10:$J$1000,6,'TRANSAKSI'!$K$10:$K$1000,TahunSel) | J13: =SUMIFS('TRANSAKSI'!$I$10:$I$1000,'TRANSAKSI'!$E$10:$E$1000,"4.1.05.01",'TRANSAKSI'!$J$10:$J$1000,7,'TRANSAKSI'!$K$10:$K$1000,TahunSel)-SUMIFS('TRANSAKSI'!$H$10:$H$1000,'TRANSAKSI'!$E$10:$E$1000,"4.1.05.01",'TRANSAKSI'!$J$10:$J$1000,7,'TRANSAKSI'!$K$10:$K$1000,TahunSel) | K13: =SUMIFS('TRANSAKSI'!$I$10:$I$1000,'TRANSAKSI'!$E$10:$E$1000,"4.1.05.01",'TRANSAKSI'!$J$10:$J$1000,8,'TRANSAKSI'!$K$10:$K$1000,TahunSel)-SUMIFS('TRANSAKSI'!$H$10:$H$1000,'TRANSAKSI'!$E$10:$E$1000,"4.1.05.01",'TRANSAKSI'!$J$10:$J$1000,8,'TRANSAKSI'!$K$10:$K$1000,TahunSel) | L13: =SUMIFS('TRANSAKSI'!$I$10:$I$1000,'TRANSAKSI'!$E$10:$E$1000,"4.1.05.01",'TRANSAKSI'!$J$10:$J$1000,9,'TRANSAKSI'!$K$10:$K$1000,TahunSel)-SUMIFS('TRANSAKSI'!$H$10:$H$1000,'TRANSAKSI'!$E$10:$E$1000,"4.1.05.01",'TRANSAKSI'!$J$10:$J$1000,9,'TRANSAKSI'!$K$10:$K$1000,TahunSel) | M13: =SUMIFS('TRANSAKSI'!$I$10:$I$1000,'TRANSAKSI'!$E$10:$E$1000,"4.1.05.01",'TRANSAKSI'!$J$10:$J$1000,10,'TRANSAKSI'!$K$10:$K$1000,TahunSel)-SUMIFS('TRANSAKSI'!$H$10:$H$1000,'TRANSAKSI'!$E$10:$E$1000,"4.1.05.01",'TRANSAKSI'!$J$10:$J$1000,10,'TRANSAKSI'!$K$10:$K$1000,TahunSel) | N13: =SUMIFS('TRANSAKSI'!$I$10:$I$1000,'TRANSAKSI'!$E$10:$E$1000,"4.1.05.01",'TRANSAKSI'!$J$10:$J$1000,11,'TRANSAKSI'!$K$10:$K$1000,TahunSel)-SUMIFS('TRANSAKSI'!$H$10:$H$1000,'TRANSAKSI'!$E$10:$E$1000,"4.1.05.01",'TRANSAKSI'!$J$10:$J$1000,11,'TRANSAKSI'!$K$10:$K$1000,TahunSel) | O13: =SUMIFS('TRANSAKSI'!$I$10:$I$1000,'TRANSAKSI'!$E$10:$E$1000,"4.1.05.01",'TRANSAKSI'!$J$10:$J$1000,12,'TRANSAKSI'!$K$10:$K$1000,TahunSel)-SUMIFS('TRANSAKSI'!$H$10:$H$1000,'TRANSAKSI'!$E$10:$E$1000,"4.1.05.01",'TRANSAKSI'!$J$10:$J$1000,12,'TRANSAKSI'!$K$10:$K$1000,TahunSel) | P13: =SUM(D13:O13)
A14: 4.1.05.03 | B14: Pendapatan Jasa Bayar BPJS | C14: Pendapatan | D14: =SUMIFS('TRANSAKSI'!$I$10:$I$1000,'TRANSAKSI'!$E$10:$E$1000,"4.1.05.03",'TRANSAKSI'!$J$10:$J$1000,1,'TRANSAKSI'!$K$10:$K$1000,TahunSel)-SUMIFS('TRANSAKSI'!$H$10:$H$1000,'TRANSAKSI'!$E$10:$E$1000,"4.1.05.03",'TRANSAKSI'!$J$10:$J$1000,1,'TRANSAKSI'!$K$10:$K$1000,TahunSel) | E14: =SUMIFS('TRANSAKSI'!$I$10:$I$1000,'TRANSAKSI'!$E$10:$E$1000,"4.1.05.03",'TRANSAKSI'!$J$10:$J$1000,2,'TRANSAKSI'!$K$10:$K$1000,TahunSel)-SUMIFS('TRANSAKSI'!$H$10:$H$1000,'TRANSAKSI'!$E$10:$E$1000,"4.1.05.03",'TRANSAKSI'!$J$10:$J$1000,2,'TRANSAKSI'!$K$10:$K$1000,TahunSel) | F14: =SUMIFS('TRANSAKSI'!$I$10:$I$1000,'TRANSAKSI'!$E$10:$E$1000,"4.1.05.03",'TRANSAKSI'!$J$10:$J$1000,3,'TRANSAKSI'!$K$10:$K$1000,TahunSel)-SUMIFS('TRANSAKSI'!$H$10:$H$1000,'TRANSAKSI'!$E$10:$E$1000,"4.1.05.03",'TRANSAKSI'!$J$10:$J$1000,3,'TRANSAKSI'!$K$10:$K$1000,TahunSel) | G14: =SUMIFS('TRANSAKSI'!$I$10:$I$1000,'TRANSAKSI'!$E$10:$E$1000,"4.1.05.03",'TRANSAKSI'!$J$10:$J$1000,4,'TRANSAKSI'!$K$10:$K$1000,TahunSel)-SUMIFS('TRANSAKSI'!$H$10:$H$1000,'TRANSAKSI'!$E$10:$E$1000,"4.1.05.03",'TRANSAKSI'!$J$10:$J$1000,4,'TRANSAKSI'!$K$10:$K$1000,TahunSel) | H14: =SUMIFS('TRANSAKSI'!$I$10:$I$1000,'TRANSAKSI'!$E$10:$E$1000,"4.1.05.03",'TRANSAKSI'!$J$10:$J$1000,5,'TRANSAKSI'!$K$10:$K$1000,TahunSel)-SUMIFS('TRANSAKSI'!$H$10:$H$1000,'TRANSAKSI'!$E$10:$E$1000,"4.1.05.03",'TRANSAKSI'!$J$10:$J$1000,5,'TRANSAKSI'!$K$10:$K$1000,TahunSel) | I14: =SUMIFS('TRANSAKSI'!$I$10:$I$1000,'TRANSAKSI'!$E$10:$E$1000,"4.1.05.03",'TRANSAKSI'!$J$10:$J$1000,6,'TRANSAKSI'!$K$10:$K$1000,TahunSel)-SUMIFS('TRANSAKSI'!$H$10:$H$1000,'TRANSAKSI'!$E$10:$E$1000,"4.1.05.03",'TRANSAKSI'!$J$10:$J$1000,6,'TRANSAKSI'!$K$10:$K$1000,TahunSel) | J14: =SUMIFS('TRANSAKSI'!$I$10:$I$1000,'TRANSAKSI'!$E$10:$E$1000,"4.1.05.03",'TRANSAKSI'!$J$10:$J$1000,7,'TRANSAKSI'!$K$10:$K$1000,TahunSel)-SUMIFS('TRANSAKSI'!$H$10:$H$1000,'TRANSAKSI'!$E$10:$E$1000,"4.1.05.03",'TRANSAKSI'!$J$10:$J$1000,7,'TRANSAKSI'!$K$10:$K$1000,TahunSel) | K14: =SUMIFS('TRANSAKSI'!$I$10:$I$1000,'TRANSAKSI'!$E$10:$E$1000,"4.1.05.03",'TRANSAKSI'!$J$10:$J$1000,8,'TRANSAKSI'!$K$10:$K$1000,TahunSel)-SUMIFS('TRANSAKSI'!$H$10:$H$1000,'TRANSAKSI'!$E$10:$E$1000,"4.1.05.03",'TRANSAKSI'!$J$10:$J$1000,8,'TRANSAKSI'!$K$10:$K$1000,TahunSel) | L14: =SUMIFS('TRANSAKSI'!$I$10:$I$1000,'TRANSAKSI'!$E$10:$E$1000,"4.1.05.03",'TRANSAKSI'!$J$10:$J$1000,9,'TRANSAKSI'!$K$10:$K$1000,TahunSel)-SUMIFS('TRANSAKSI'!$H$10:$H$1000,'TRANSAKSI'!$E$10:$E$1000,"4.1.05.03",'TRANSAKSI'!$J$10:$J$1000,9,'TRANSAKSI'!$K$10:$K$1000,TahunSel) | M14: =SUMIFS('TRANSAKSI'!$I$10:$I$1000,'TRANSAKSI'!$E$10:$E$1000,"4.1.05.03",'TRANSAKSI'!$J$10:$J$1000,10,'TRANSAKSI'!$K$10:$K$1000,TahunSel)-SUMIFS('TRANSAKSI'!$H$10:$H$1000,'TRANSAKSI'!$E$10:$E$1000,"4.1.05.03",'TRANSAKSI'!$J$10:$J$1000,10,'TRANSAKSI'!$K$10:$K$1000,TahunSel) | N14: =SUMIFS('TRANSAKSI'!$I$10:$I$1000,'TRANSAKSI'!$E$10:$E$1000,"4.1.05.03",'TRANSAKSI'!$J$10:$J$1000,11,'TRANSAKSI'!$K$10:$K$1000,TahunSel)-SUMIFS('TRANSAKSI'!$H$10:$H$1000,'TRANSAKSI'!$E$10:$E$1000,"4.1.05.03",'TRANSAKSI'!$J$10:$J$1000,11,'TRANSAKSI'!$K$10:$K$1000,TahunSel) | O14: =SUMIFS('TRANSAKSI'!$I$10:$I$1000,'TRANSAKSI'!$E$10:$E$1000,"4.1.05.03",'TRANSAKSI'!$J$10:$J$1000,12,'TRANSAKSI'!$K$10:$K$1000,TahunSel)-SUMIFS('TRANSAKSI'!$H$10:$H$1000,'TRANSAKSI'!$E$10:$E$1000,"4.1.05.03",'TRANSAKSI'!$J$10:$J$1000,12,'TRANSAKSI'!$K$10:$K$1000,TahunSel) | P14: =SUM(D14:O14)
A15: 4.1.08.01 | B15: Pendapatan Simpan Pinjam | C15: Pendapatan | D15: =SUMIFS('TRANSAKSI'!$I$10:$I$1000,'TRANSAKSI'!$E$10:$E$1000,"4.1.08.01",'TRANSAKSI'!$J$10:$J$1000,1,'TRANSAKSI'!$K$10:$K$1000,TahunSel)-SUMIFS('TRANSAKSI'!$H$10:$H$1000,'TRANSAKSI'!$E$10:$E$1000,"4.1.08.01",'TRANSAKSI'!$J$10:$J$1000,1,'TRANSAKSI'!$K$10:$K$1000,TahunSel) | E15: =SUMIFS('TRANSAKSI'!$I$10:$I$1000,'TRANSAKSI'!$E$10:$E$1000,"4.1.08.01",'TRANSAKSI'!$J$10:$J$1000,2,'TRANSAKSI'!$K$10:$K$1000,TahunSel)-SUMIFS('TRANSAKSI'!$H$10:$H$1000,'TRANSAKSI'!$E$10:$E$1000,"4.1.08.01",'TRANSAKSI'!$J$10:$J$1000,2,'TRANSAKSI'!$K$10:$K$1000,TahunSel) | F15: =SUMIFS('TRANSAKSI'!$I$10:$I$1000,'TRANSAKSI'!$E$10:$E$1000,"4.1.08.01",'TRANSAKSI'!$J$10:$J$1000,3,'TRANSAKSI'!$K$10:$K$1000,TahunSel)-SUMIFS('TRANSAKSI'!$H$10:$H$1000,'TRANSAKSI'!$E$10:$E$1000,"4.1.08.01",'TRANSAKSI'!$J$10:$J$1000,3,'TRANSAKSI'!$K$10:$K$1000,TahunSel) | G15: =SUMIFS('TRANSAKSI'!$I$10:$I$1000,'TRANSAKSI'!$E$10:$E$1000,"4.1.08.01",'TRANSAKSI'!$J$10:$J$1000,4,'TRANSAKSI'!$K$10:$K$1000,TahunSel)-SUMIFS('TRANSAKSI'!$H$10:$H$1000,'TRANSAKSI'!$E$10:$E$1000,"4.1.08.01",'TRANSAKSI'!$J$10:$J$1000,4,'TRANSAKSI'!$K$10:$K$1000,TahunSel) | H15: =SUMIFS('TRANSAKSI'!$I$10:$I$1000,'TRANSAKSI'!$E$10:$E$1000,"4.1.08.01",'TRANSAKSI'!$J$10:$J$1000,5,'TRANSAKSI'!$K$10:$K$1000,TahunSel)-SUMIFS('TRANSAKSI'!$H$10:$H$1000,'TRANSAKSI'!$E$10:$E$1000,"4.1.08.01",'TRANSAKSI'!$J$10:$J$1000,5,'TRANSAKSI'!$K$10:$K$1000,TahunSel) | I15: =SUMIFS('TRANSAKSI'!$I$10:$I$1000,'TRANSAKSI'!$E$10:$E$1000,"4.1.08.01",'TRANSAKSI'!$J$10:$J$1000,6,'TRANSAKSI'!$K$10:$K$1000,TahunSel)-SUMIFS('TRANSAKSI'!$H$10:$H$1000,'TRANSAKSI'!$E$10:$E$1000,"4.1.08.01",'TRANSAKSI'!$J$10:$J$1000,6,'TRANSAKSI'!$K$10:$K$1000,TahunSel) | J15: =SUMIFS('TRANSAKSI'!$I$10:$I$1000,'TRANSAKSI'!$E$10:$E$1000,"4.1.08.01",'TRANSAKSI'!$J$10:$J$1000,7,'TRANSAKSI'!$K$10:$K$1000,TahunSel)-SUMIFS('TRANSAKSI'!$H$10:$H$1000,'TRANSAKSI'!$E$10:$E$1000,"4.1.08.01",'TRANSAKSI'!$J$10:$J$1000,7,'TRANSAKSI'!$K$10:$K$1000,TahunSel) | K15: =SUMIFS('TRANSAKSI'!$I$10:$I$1000,'TRANSAKSI'!$E$10:$E$1000,"4.1.08.01",'TRANSAKSI'!$J$10:$J$1000,8,'TRANSAKSI'!$K$10:$K$1000,TahunSel)-SUMIFS('TRANSAKSI'!$H$10:$H$1000,'TRANSAKSI'!$E$10:$E$1000,"4.1.08.01",'TRANSAKSI'!$J$10:$J$1000,8,'TRANSAKSI'!$K$10:$K$1000,TahunSel) | L15: =SUMIFS('TRANSAKSI'!$I$10:$I$1000,'TRANSAKSI'!$E$10:$E$1000,"4.1.08.01",'TRANSAKSI'!$J$10:$J$1000,9,'TRANSAKSI'!$K$10:$K$1000,TahunSel)-SUMIFS('TRANSAKSI'!$H$10:$H$1000,'TRANSAKSI'!$E$10:$E$1000,"4.1.08.01",'TRANSAKSI'!$J$10:$J$1000,9,'TRANSAKSI'!$K$10:$K$1000,TahunSel) | M15: =SUMIFS('TRANSAKSI'!$I$10:$I$1000,'TRANSAKSI'!$E$10:$E$1000,"4.1.08.01",'TRANSAKSI'!$J$10:$J$1000,10,'TRANSAKSI'!$K$10:$K$1000,TahunSel)-SUMIFS('TRANSAKSI'!$H$10:$H$1000,'TRANSAKSI'!$E$10:$E$1000,"4.1.08.01",'TRANSAKSI'!$J$10:$J$1000,10,'TRANSAKSI'!$K$10:$K$1000,TahunSel) | N15: =SUMIFS('TRANSAKSI'!$I$10:$I$1000,'TRANSAKSI'!$E$10:$E$1000,"4.1.08.01",'TRANSAKSI'!$J$10:$J$1000,11,'TRANSAKSI'!$K$10:$K$1000,TahunSel)-SUMIFS('TRANSAKSI'!$H$10:$H$1000,'TRANSAKSI'!$E$10:$E$1000,"4.1.08.01",'TRANSAKSI'!$J$10:$J$1000,11,'TRANSAKSI'!$K$10:$K$1000,TahunSel) | O15: =SUMIFS('TRANSAKSI'!$I$10:$I$1000,'TRANSAKSI'!$E$10:$E$1000,"4.1.08.01",'TRANSAKSI'!$J$10:$J$1000,12,'TRANSAKSI'!$K$10:$K$1000,TahunSel)-SUMIFS('TRANSAKSI'!$H$10:$H$1000,'TRANSAKSI'!$E$10:$E$1000,"4.1.08.01",'TRANSAKSI'!$J$10:$J$1000,12,'TRANSAKSI'!$K$10:$K$1000,TahunSel) | P15: =SUM(D15:O15)
A16: 4.1.11.01 | B16: Pendapatan Komisi | C16: Pendapatan | D16: =SUMIFS('TRANSAKSI'!$I$10:$I$1000,'TRANSAKSI'!$E$10:$E$1000,"4.1.11.01",'TRANSAKSI'!$J$10:$J$1000,1,'TRANSAKSI'!$K$10:$K$1000,TahunSel)-SUMIFS('TRANSAKSI'!$H$10:$H$1000,'TRANSAKSI'!$E$10:$E$1000,"4.1.11.01",'TRANSAKSI'!$J$10:$J$1000,1,'TRANSAKSI'!$K$10:$K$1000,TahunSel) | E16: =SUMIFS('TRANSAKSI'!$I$10:$I$1000,'TRANSAKSI'!$E$10:$E$1000,"4.1.11.01",'TRANSAKSI'!$J$10:$J$1000,2,'TRANSAKSI'!$K$10:$K$1000,TahunSel)-SUMIFS('TRANSAKSI'!$H$10:$H$1000,'TRANSAKSI'!$E$10:$E$1000,"4.1.11.01",'TRANSAKSI'!$J$10:$J$1000,2,'TRANSAKSI'!$K$10:$K$1000,TahunSel) | F16: =SUMIFS('TRANSAKSI'!$I$10:$I$1000,'TRANSAKSI'!$E$10:$E$1000,"4.1.11.01",'TRANSAKSI'!$J$10:$J$1000,3,'TRANSAKSI'!$K$10:$K$1000,TahunSel)-SUMIFS('TRANSAKSI'!$H$10:$H$1000,'TRANSAKSI'!$E$10:$E$1000,"4.1.11.01",'TRANSAKSI'!$J$10:$J$1000,3,'TRANSAKSI'!$K$10:$K$1000,TahunSel) | G16: =SUMIFS('TRANSAKSI'!$I$10:$I$1000,'TRANSAKSI'!$E$10:$E$1000,"4.1.11.01",'TRANSAKSI'!$J$10:$J$1000,4,'TRANSAKSI'!$K$10:$K$1000,TahunSel)-SUMIFS('TRANSAKSI'!$H$10:$H$1000,'TRANSAKSI'!$E$10:$E$1000,"4.1.11.01",'TRANSAKSI'!$J$10:$J$1000,4,'TRANSAKSI'!$K$10:$K$1000,TahunSel) | H16: =SUMIFS('TRANSAKSI'!$I$10:$I$1000,'TRANSAKSI'!$E$10:$E$1000,"4.1.11.01",'TRANSAKSI'!$J$10:$J$1000,5,'TRANSAKSI'!$K$10:$K$1000,TahunSel)-SUMIFS('TRANSAKSI'!$H$10:$H$1000,'TRANSAKSI'!$E$10:$E$1000,"4.1.11.01",'TRANSAKSI'!$J$10:$J$1000,5,'TRANSAKSI'!$K$10:$K$1000,TahunSel) | I16: =SUMIFS('TRANSAKSI'!$I$10:$I$1000,'TRANSAKSI'!$E$10:$E$1000,"4.1.11.01",'TRANSAKSI'!$J$10:$J$1000,6,'TRANSAKSI'!$K$10:$K$1000,TahunSel)-SUMIFS('TRANSAKSI'!$H$10:$H$1000,'TRANSAKSI'!$E$10:$E$1000,"4.1.11.01",'TRANSAKSI'!$J$10:$J$1000,6,'TRANSAKSI'!$K$10:$K$1000,TahunSel) | J16: =SUMIFS('TRANSAKSI'!$I$10:$I$1000,'TRANSAKSI'!$E$10:$E$1000,"4.1.11.01",'TRANSAKSI'!$J$10:$J$1000,7,'TRANSAKSI'!$K$10:$K$1000,TahunSel)-SUMIFS('TRANSAKSI'!$H$10:$H$1000,'TRANSAKSI'!$E$10:$E$1000,"4.1.11.01",'TRANSAKSI'!$J$10:$J$1000,7,'TRANSAKSI'!$K$10:$K$1000,TahunSel) | K16: =SUMIFS('TRANSAKSI'!$I$10:$I$1000,'TRANSAKSI'!$E$10:$E$1000,"4.1.11.01",'TRANSAKSI'!$J$10:$J$1000,8,'TRANSAKSI'!$K$10:$K$1000,TahunSel)-SUMIFS('TRANSAKSI'!$H$10:$H$1000,'TRANSAKSI'!$E$10:$E$1000,"4.1.11.01",'TRANSAKSI'!$J$10:$J$1000,8,'TRANSAKSI'!$K$10:$K$1000,TahunSel) | L16: =SUMIFS('TRANSAKSI'!$I$10:$I$1000,'TRANSAKSI'!$E$10:$E$1000,"4.1.11.01",'TRANSAKSI'!$J$10:$J$1000,9,'TRANSAKSI'!$K$10:$K$1000,TahunSel)-SUMIFS('TRANSAKSI'!$H$10:$H$1000,'TRANSAKSI'!$E$10:$E$1000,"4.1.11.01",'TRANSAKSI'!$J$10:$J$1000,9,'TRANSAKSI'!$K$10:$K$1000,TahunSel) | M16: =SUMIFS('TRANSAKSI'!$I$10:$I$1000,'TRANSAKSI'!$E$10:$E$1000,"4.1.11.01",'TRANSAKSI'!$J$10:$J$1000,10,'TRANSAKSI'!$K$10:$K$1000,TahunSel)-SUMIFS('TRANSAKSI'!$H$10:$H$1000,'TRANSAKSI'!$E$10:$E$1000,"4.1.11.01",'TRANSAKSI'!$J$10:$J$1000,10,'TRANSAKSI'!$K$10:$K$1000,TahunSel) | N16: =SUMIFS('TRANSAKSI'!$I$10:$I$1000,'TRANSAKSI'!$E$10:$E$1000,"4.1.11.01",'TRANSAKSI'!$J$10:$J$1000,11,'TRANSAKSI'!$K$10:$K$1000,TahunSel)-SUMIFS('TRANSAKSI'!$H$10:$H$1000,'TRANSAKSI'!$E$10:$E$1000,"4.1.11.01",'TRANSAKSI'!$J$10:$J$1000,11,'TRANSAKSI'!$K$10:$K$1000,TahunSel) | O16: =SUMIFS('TRANSAKSI'!$I$10:$I$1000,'TRANSAKSI'!$E$10:$E$1000,"4.1.11.01",'TRANSAKSI'!$J$10:$J$1000,12,'TRANSAKSI'!$K$10:$K$1000,TahunSel)-SUMIFS('TRANSAKSI'!$H$10:$H$1000,'TRANSAKSI'!$E$10:$E$1000,"4.1.11.01",'TRANSAKSI'!$J$10:$J$1000,12,'TRANSAKSI'!$K$10:$K$1000,TahunSel) | P16: =SUM(D16:O16)
A17: 4.1.12.01 | B17: Pendapatan Penjualan Jagung | C17: Pendapatan | D17: =SUMIFS('TRANSAKSI'!$I$10:$I$1000,'TRANSAKSI'!$E$10:$E$1000,"4.1.12.01",'TRANSAKSI'!$J$10:$J$1000,1,'TRANSAKSI'!$K$10:$K$1000,TahunSel)-SUMIFS('TRANSAKSI'!$H$10:$H$1000,'TRANSAKSI'!$E$10:$E$1000,"4.1.12.01",'TRANSAKSI'!$J$10:$J$1000,1,'TRANSAKSI'!$K$10:$K$1000,TahunSel) | E17: =SUMIFS('TRANSAKSI'!$I$10:$I$1000,'TRANSAKSI'!$E$10:$E$1000,"4.1.12.01",'TRANSAKSI'!$J$10:$J$1000,2,'TRANSAKSI'!$K$10:$K$1000,TahunSel)-SUMIFS('TRANSAKSI'!$H$10:$H$1000,'TRANSAKSI'!$E$10:$E$1000,"4.1.12.01",'TRANSAKSI'!$J$10:$J$1000,2,'TRANSAKSI'!$K$10:$K$1000,TahunSel) | F17: =SUMIFS('TRANSAKSI'!$I$10:$I$1000,'TRANSAKSI'!$E$10:$E$1000,"4.1.12.01",'TRANSAKSI'!$J$10:$J$1000,3,'TRANSAKSI'!$K$10:$K$1000,TahunSel)-SUMIFS('TRANSAKSI'!$H$10:$H$1000,'TRANSAKSI'!$E$10:$E$1000,"4.1.12.01",'TRANSAKSI'!$J$10:$J$1000,3,'TRANSAKSI'!$K$10:$K$1000,TahunSel) | G17: =SUMIFS('TRANSAKSI'!$I$10:$I$1000,'TRANSAKSI'!$E$10:$E$1000,"4.1.12.01",'TRANSAKSI'!$J$10:$J$1000,4,'TRANSAKSI'!$K$10:$K$1000,TahunSel)-SUMIFS('TRANSAKSI'!$H$10:$H$1000,'TRANSAKSI'!$E$10:$E$1000,"4.1.12.01",'TRANSAKSI'!$J$10:$J$1000,4,'TRANSAKSI'!$K$10:$K$1000,TahunSel) | H17: =SUMIFS('TRANSAKSI'!$I$10:$I$1000,'TRANSAKSI'!$E$10:$E$1000,"4.1.12.01",'TRANSAKSI'!$J$10:$J$1000,5,'TRANSAKSI'!$K$10:$K$1000,TahunSel)-SUMIFS('TRANSAKSI'!$H$10:$H$1000,'TRANSAKSI'!$E$10:$E$1000,"4.1.12.01",'TRANSAKSI'!$J$10:$J$1000,5,'TRANSAKSI'!$K$10:$K$1000,TahunSel) | I17: =SUMIFS('TRANSAKSI'!$I$10:$I$1000,'TRANSAKSI'!$E$10:$E$1000,"4.1.12.01",'TRANSAKSI'!$J$10:$J$1000,6,'TRANSAKSI'!$K$10:$K$1000,TahunSel)-SUMIFS('TRANSAKSI'!$H$10:$H$1000,'TRANSAKSI'!$E$10:$E$1000,"4.1.12.01",'TRANSAKSI'!$J$10:$J$1000,6,'TRANSAKSI'!$K$10:$K$1000,TahunSel) | J17: =SUMIFS('TRANSAKSI'!$I$10:$I$1000,'TRANSAKSI'!$E$10:$E$1000,"4.1.12.01",'TRANSAKSI'!$J$10:$J$1000,7,'TRANSAKSI'!$K$10:$K$1000,TahunSel)-SUMIFS('TRANSAKSI'!$H$10:$H$1000,'TRANSAKSI'!$E$10:$E$1000,"4.1.12.01",'TRANSAKSI'!$J$10:$J$1000,7,'TRANSAKSI'!$K$10:$K$1000,TahunSel) | K17: =SUMIFS('TRANSAKSI'!$I$10:$I$1000,'TRANSAKSI'!$E$10:$E$1000,"4.1.12.01",'TRANSAKSI'!$J$10:$J$1000,8,'TRANSAKSI'!$K$10:$K$1000,TahunSel)-SUMIFS('TRANSAKSI'!$H$10:$H$1000,'TRANSAKSI'!$E$10:$E$1000,"4.1.12.01",'TRANSAKSI'!$J$10:$J$1000,8,'TRANSAKSI'!$K$10:$K$1000,TahunSel) | L17: =SUMIFS('TRANSAKSI'!$I$10:$I$1000,'TRANSAKSI'!$E$10:$E$1000,"4.1.12.01",'TRANSAKSI'!$J$10:$J$1000,9,'TRANSAKSI'!$K$10:$K$1000,TahunSel)-SUMIFS('TRANSAKSI'!$H$10:$H$1000,'TRANSAKSI'!$E$10:$E$1000,"4.1.12.01",'TRANSAKSI'!$J$10:$J$1000,9,'TRANSAKSI'!$K$10:$K$1000,TahunSel) | M17: =SUMIFS('TRANSAKSI'!$I$10:$I$1000,'TRANSAKSI'!$E$10:$E$1000,"4.1.12.01",'TRANSAKSI'!$J$10:$J$1000,10,'TRANSAKSI'!$K$10:$K$1000,TahunSel)-SUMIFS('TRANSAKSI'!$H$10:$H$1000,'TRANSAKSI'!$E$10:$E$1000,"4.1.12.01",'TRANSAKSI'!$J$10:$J$1000,10,'TRANSAKSI'!$K$10:$K$1000,TahunSel) | N17: =SUMIFS('TRANSAKSI'!$I$10:$I$1000,'TRANSAKSI'!$E$10:$E$1000,"4.1.12.01",'TRANSAKSI'!$J$10:$J$1000,11,'TRANSAKSI'!$K$10:$K$1000,TahunSel)-SUMIFS('TRANSAKSI'!$H$10:$H$1000,'TRANSAKSI'!$E$10:$E$1000,"4.1.12.01",'TRANSAKSI'!$J$10:$J$1000,11,'TRANSAKSI'!$K$10:$K$1000,TahunSel) | O17: =SUMIFS('TRANSAKSI'!$I$10:$I$1000,'TRANSAKSI'!$E$10:$E$1000,"4.1.12.01",'TRANSAKSI'!$J$10:$J$1000,12,'TRANSAKSI'!$K$10:$K$1000,TahunSel)-SUMIFS('TRANSAKSI'!$H$10:$H$1000,'TRANSAKSI'!$E$10:$E$1000,"4.1.12.01",'TRANSAKSI'!$J$10:$J$1000,12,'TRANSAKSI'!$K$10:$K$1000,TahunSel) | P17: =SUM(D17:O17)
A18: 4.1.12.02 | B18: Pendapatan Penjualan Padi | C18: Pendapatan | D18: =SUMIFS('TRANSAKSI'!$I$10:$I$1000,'TRANSAKSI'!$E$10:$E$1000,"4.1.12.02",'TRANSAKSI'!$J$10:$J$1000,1,'TRANSAKSI'!$K$10:$K$1000,TahunSel)-SUMIFS('TRANSAKSI'!$H$10:$H$1000,'TRANSAKSI'!$E$10:$E$1000,"4.1.12.02",'TRANSAKSI'!$J$10:$J$1000,1,'TRANSAKSI'!$K$10:$K$1000,TahunSel) | E18: =SUMIFS('TRANSAKSI'!$I$10:$I$1000,'TRANSAKSI'!$E$10:$E$1000,"4.1.12.02",'TRANSAKSI'!$J$10:$J$1000,2,'TRANSAKSI'!$K$10:$K$1000,TahunSel)-SUMIFS('TRANSAKSI'!$H$10:$H$1000,'TRANSAKSI'!$E$10:$E$1000,"4.1.12.02",'TRANSAKSI'!$J$10:$J$1000,2,'TRANSAKSI'!$K$10:$K$1000,TahunSel) | F18: =SUMIFS('TRANSAKSI'!$I$10:$I$1000,'TRANSAKSI'!$E$10:$E$1000,"4.1.12.02",'TRANSAKSI'!$J$10:$J$1000,3,'TRANSAKSI'!$K$10:$K$1000,TahunSel)-SUMIFS('TRANSAKSI'!$H$10:$H$1000,'TRANSAKSI'!$E$10:$E$1000,"4.1.12.02",'TRANSAKSI'!$J$10:$J$1000,3,'TRANSAKSI'!$K$10:$K$1000,TahunSel) | G18: =SUMIFS('TRANSAKSI'!$I$10:$I$1000,'TRANSAKSI'!$E$10:$E$1000,"4.1.12.02",'TRANSAKSI'!$J$10:$J$1000,4,'TRANSAKSI'!$K$10:$K$1000,TahunSel)-SUMIFS('TRANSAKSI'!$H$10:$H$1000,'TRANSAKSI'!$E$10:$E$1000,"4.1.12.02",'TRANSAKSI'!$J$10:$J$1000,4,'TRANSAKSI'!$K$10:$K$1000,TahunSel) | H18: =SUMIFS('TRANSAKSI'!$I$10:$I$1000,'TRANSAKSI'!$E$10:$E$1000,"4.1.12.02",'TRANSAKSI'!$J$10:$J$1000,5,'TRANSAKSI'!$K$10:$K$1000,TahunSel)-SUMIFS('TRANSAKSI'!$H$10:$H$1000,'TRANSAKSI'!$E$10:$E$1000,"4.1.12.02",'TRANSAKSI'!$J$10:$J$1000,5,'TRANSAKSI'!$K$10:$K$1000,TahunSel) | I18: =SUMIFS('TRANSAKSI'!$I$10:$I$1000,'TRANSAKSI'!$E$10:$E$1000,"4.1.12.02",'TRANSAKSI'!$J$10:$J$1000,6,'TRANSAKSI'!$K$10:$K$1000,TahunSel)-SUMIFS('TRANSAKSI'!$H$10:$H$1000,'TRANSAKSI'!$E$10:$E$1000,"4.1.12.02",'TRANSAKSI'!$J$10:$J$1000,6,'TRANSAKSI'!$K$10:$K$1000,TahunSel) | J18: =SUMIFS('TRANSAKSI'!$I$10:$I$1000,'TRANSAKSI'!$E$10:$E$1000,"4.1.12.02",'TRANSAKSI'!$J$10:$J$1000,7,'TRANSAKSI'!$K$10:$K$1000,TahunSel)-SUMIFS('TRANSAKSI'!$H$10:$H$1000,'TRANSAKSI'!$E$10:$E$1000,"4.1.12.02",'TRANSAKSI'!$J$10:$J$1000,7,'TRANSAKSI'!$K$10:$K$1000,TahunSel) | K18: =SUMIFS('TRANSAKSI'!$I$10:$I$1000,'TRANSAKSI'!$E$10:$E$1000,"4.1.12.02",'TRANSAKSI'!$J$10:$J$1000,8,'TRANSAKSI'!$K$10:$K$1000,TahunSel)-SUMIFS('TRANSAKSI'!$H$10:$H$1000,'TRANSAKSI'!$E$10:$E$1000,"4.1.12.02",'TRANSAKSI'!$J$10:$J$1000,8,'TRANSAKSI'!$K$10:$K$1000,TahunSel) | L18: =SUMIFS('TRANSAKSI'!$I$10:$I$1000,'TRANSAKSI'!$E$10:$E$1000,"4.1.12.02",'TRANSAKSI'!$J$10:$J$1000,9,'TRANSAKSI'!$K$10:$K$1000,TahunSel)-SUMIFS('TRANSAKSI'!$H$10:$H$1000,'TRANSAKSI'!$E$10:$E$1000,"4.1.12.02",'TRANSAKSI'!$J$10:$J$1000,9,'TRANSAKSI'!$K$10:$K$1000,TahunSel) | M18: =SUMIFS('TRANSAKSI'!$I$10:$I$1000,'TRANSAKSI'!$E$10:$E$1000,"4.1.12.02",'TRANSAKSI'!$J$10:$J$1000,10,'TRANSAKSI'!$K$10:$K$1000,TahunSel)-SUMIFS('TRANSAKSI'!$H$10:$H$1000,'TRANSAKSI'!$E$10:$E$1000,"4.1.12.02",'TRANSAKSI'!$J$10:$J$1000,10,'TRANSAKSI'!$K$10:$K$1000,TahunSel) | N18: =SUMIFS('TRANSAKSI'!$I$10:$I$1000,'TRANSAKSI'!$E$10:$E$1000,"4.1.12.02",'TRANSAKSI'!$J$10:$J$1000,11,'TRANSAKSI'!$K$10:$K$1000,TahunSel)-SUMIFS('TRANSAKSI'!$H$10:$H$1000,'TRANSAKSI'!$E$10:$E$1000,"4.1.12.02",'TRANSAKSI'!$J$10:$J$1000,11,'TRANSAKSI'!$K$10:$K$1000,TahunSel) | O18: =SUMIFS('TRANSAKSI'!$I$10:$I$1000,'TRANSAKSI'!$E$10:$E$1000,"4.1.12.02",'TRANSAKSI'!$J$10:$J$1000,12,'TRANSAKSI'!$K$10:$K$1000,TahunSel)-SUMIFS('TRANSAKSI'!$H$10:$H$1000,'TRANSAKSI'!$E$10:$E$1000,"4.1.12.02",'TRANSAKSI'!$J$10:$J$1000,12,'TRANSAKSI'!$K$10:$K$1000,TahunSel) | P18: =SUM(D18:O18)
A19: 4.1.13.05 | B19: Pendapatan Penjualan Telur Ayam | C19: Pendapatan | D19: =SUMIFS('TRANSAKSI'!$I$10:$I$1000,'TRANSAKSI'!$E$10:$E$1000,"4.1.13.05",'TRANSAKSI'!$J$10:$J$1000,1,'TRANSAKSI'!$K$10:$K$1000,TahunSel)-SUMIFS('TRANSAKSI'!$H$10:$H$1000,'TRANSAKSI'!$E$10:$E$1000,"4.1.13.05",'TRANSAKSI'!$J$10:$J$1000,1,'TRANSAKSI'!$K$10:$K$1000,TahunSel) | E19: =SUMIFS('TRANSAKSI'!$I$10:$I$1000,'TRANSAKSI'!$E$10:$E$1000,"4.1.13.05",'TRANSAKSI'!$J$10:$J$1000,2,'TRANSAKSI'!$K$10:$K$1000,TahunSel)-SUMIFS('TRANSAKSI'!$H$10:$H$1000,'TRANSAKSI'!$E$10:$E$1000,"4.1.13.05",'TRANSAKSI'!$J$10:$J$1000,2,'TRANSAKSI'!$K$10:$K$1000,TahunSel) | F19: =SUMIFS('TRANSAKSI'!$I$10:$I$1000,'TRANSAKSI'!$E$10:$E$1000,"4.1.13.05",'TRANSAKSI'!$J$10:$J$1000,3,'TRANSAKSI'!$K$10:$K$1000,TahunSel)-SUMIFS('TRANSAKSI'!$H$10:$H$1000,'TRANSAKSI'!$E$10:$E$1000,"4.1.13.05",'TRANSAKSI'!$J$10:$J$1000,3,'TRANSAKSI'!$K$10:$K$1000,TahunSel) | G19: =SUMIFS('TRANSAKSI'!$I$10:$I$1000,'TRANSAKSI'!$E$10:$E$1000,"4.1.13.05",'TRANSAKSI'!$J$10:$J$1000,4,'TRANSAKSI'!$K$10:$K$1000,TahunSel)-SUMIFS('TRANSAKSI'!$H$10:$H$1000,'TRANSAKSI'!$E$10:$E$1000,"4.1.13.05",'TRANSAKSI'!$J$10:$J$1000,4,'TRANSAKSI'!$K$10:$K$1000,TahunSel) | H19: =SUMIFS('TRANSAKSI'!$I$10:$I$1000,'TRANSAKSI'!$E$10:$E$1000,"4.1.13.05",'TRANSAKSI'!$J$10:$J$1000,5,'TRANSAKSI'!$K$10:$K$1000,TahunSel)-SUMIFS('TRANSAKSI'!$H$10:$H$1000,'TRANSAKSI'!$E$10:$E$1000,"4.1.13.05",'TRANSAKSI'!$J$10:$J$1000,5,'TRANSAKSI'!$K$10:$K$1000,TahunSel) | I19: =SUMIFS('TRANSAKSI'!$I$10:$I$1000,'TRANSAKSI'!$E$10:$E$1000,"4.1.13.05",'TRANSAKSI'!$J$10:$J$1000,6,'TRANSAKSI'!$K$10:$K$1000,TahunSel)-SUMIFS('TRANSAKSI'!$H$10:$H$1000,'TRANSAKSI'!$E$10:$E$1000,"4.1.13.05",'TRANSAKSI'!$J$10:$J$1000,6,'TRANSAKSI'!$K$10:$K$1000,TahunSel) | J19: =SUMIFS('TRANSAKSI'!$I$10:$I$1000,'TRANSAKSI'!$E$10:$E$1000,"4.1.13.05",'TRANSAKSI'!$J$10:$J$1000,7,'TRANSAKSI'!$K$10:$K$1000,TahunSel)-SUMIFS('TRANSAKSI'!$H$10:$H$1000,'TRANSAKSI'!$E$10:$E$1000,"4.1.13.05",'TRANSAKSI'!$J$10:$J$1000,7,'TRANSAKSI'!$K$10:$K$1000,TahunSel) | K19: =SUMIFS('TRANSAKSI'!$I$10:$I$1000,'TRANSAKSI'!$E$10:$E$1000,"4.1.13.05",'TRANSAKSI'!$J$10:$J$1000,8,'TRANSAKSI'!$K$10:$K$1000,TahunSel)-SUMIFS('TRANSAKSI'!$H$10:$H$1000,'TRANSAKSI'!$E$10:$E$1000,"4.1.13.05",'TRANSAKSI'!$J$10:$J$1000,8,'TRANSAKSI'!$K$10:$K$1000,TahunSel) | L19: =SUMIFS('TRANSAKSI'!$I$10:$I$1000,'TRANSAKSI'!$E$10:$E$1000,"4.1.13.05",'TRANSAKSI'!$J$10:$J$1000,9,'TRANSAKSI'!$K$10:$K$1000,TahunSel)-SUMIFS('TRANSAKSI'!$H$10:$H$1000,'TRANSAKSI'!$E$10:$E$1000,"4.1.13.05",'TRANSAKSI'!$J$10:$J$1000,9,'TRANSAKSI'!$K$10:$K$1000,TahunSel) | M19: =SUMIFS('TRANSAKSI'!$I$10:$I$1000,'TRANSAKSI'!$E$10:$E$1000,"4.1.13.05",'TRANSAKSI'!$J$10:$J$1000,10,'TRANSAKSI'!$K$10:$K$1000,TahunSel)-SUMIFS('TRANSAKSI'!$H$10:$H$1000,'TRANSAKSI'!$E$10:$E$1000,"4.1.13.05",'TRANSAKSI'!$J$10:$J$1000,10,'TRANSAKSI'!$K$10:$K$1000,TahunSel) | N19: =SUMIFS('TRANSAKSI'!$I$10:$I$1000,'TRANSAKSI'!$E$10:$E$1000,"4.1.13.05",'TRANSAKSI'!$J$10:$J$1000,11,'TRANSAKSI'!$K$10:$K$1000,TahunSel)-SUMIFS('TRANSAKSI'!$H$10:$H$1000,'TRANSAKSI'!$E$10:$E$1000,"4.1.13.05",'TRANSAKSI'!$J$10:$J$1000,11,'TRANSAKSI'!$K$10:$K$1000,TahunSel) | O19: =SUMIFS('TRANSAKSI'!$I$10:$I$1000,'TRANSAKSI'!$E$10:$E$1000,"4.1.13.05",'TRANSAKSI'!$J$10:$J$1000,12,'TRANSAKSI'!$K$10:$K$1000,TahunSel)-SUMIFS('TRANSAKSI'!$H$10:$H$1000,'TRANSAKSI'!$E$10:$E$1000,"4.1.13.05",'TRANSAKSI'!$J$10:$J$1000,12,'TRANSAKSI'!$K$10:$K$1000,TahunSel) | P19: =SUM(D19:O19)
A20: 4.1.14.01 | B20: Pendapatan Penjualan Lele | C20: Pendapatan | D20: =SUMIFS('TRANSAKSI'!$I$10:$I$1000,'TRANSAKSI'!$E$10:$E$1000,"4.1.14.01",'TRANSAKSI'!$J$10:$J$1000,1,'TRANSAKSI'!$K$10:$K$1000,TahunSel)-SUMIFS('TRANSAKSI'!$H$10:$H$1000,'TRANSAKSI'!$E$10:$E$1000,"4.1.14.01",'TRANSAKSI'!$J$10:$J$1000,1,'TRANSAKSI'!$K$10:$K$1000,TahunSel) | E20: =SUMIFS('TRANSAKSI'!$I$10:$I$1000,'TRANSAKSI'!$E$10:$E$1000,"4.1.14.01",'TRANSAKSI'!$J$10:$J$1000,2,'TRANSAKSI'!$K$10:$K$1000,TahunSel)-SUMIFS('TRANSAKSI'!$H$10:$H$1000,'TRANSAKSI'!$E$10:$E$1000,"4.1.14.01",'TRANSAKSI'!$J$10:$J$1000,2,'TRANSAKSI'!$K$10:$K$1000,TahunSel) | F20: =SUMIFS('TRANSAKSI'!$I$10:$I$1000,'TRANSAKSI'!$E$10:$E$1000,"4.1.14.01",'TRANSAKSI'!$J$10:$J$1000,3,'TRANSAKSI'!$K$10:$K$1000,TahunSel)-SUMIFS('TRANSAKSI'!$H$10:$H$1000,'TRANSAKSI'!$E$10:$E$1000,"4.1.14.01",'TRANSAKSI'!$J$10:$J$1000,3,'TRANSAKSI'!$K$10:$K$1000,TahunSel) | G20: =SUMIFS('TRANSAKSI'!$I$10:$I$1000,'TRANSAKSI'!$E$10:$E$1000,"4.1.14.01",'TRANSAKSI'!$J$10:$J$1000,4,'TRANSAKSI'!$K$10:$K$1000,TahunSel)-SUMIFS('TRANSAKSI'!$H$10:$H$1000,'TRANSAKSI'!$E$10:$E$1000,"4.1.14.01",'TRANSAKSI'!$J$10:$J$1000,4,'TRANSAKSI'!$K$10:$K$1000,TahunSel) | H20: =SUMIFS('TRANSAKSI'!$I$10:$I$1000,'TRANSAKSI'!$E$10:$E$1000,"4.1.14.01",'TRANSAKSI'!$J$10:$J$1000,5,'TRANSAKSI'!$K$10:$K$1000,TahunSel)-SUMIFS('TRANSAKSI'!$H$10:$H$1000,'TRANSAKSI'!$E$10:$E$1000,"4.1.14.01",'TRANSAKSI'!$J$10:$J$1000,5,'TRANSAKSI'!$K$10:$K$1000,TahunSel) | I20: =SUMIFS('TRANSAKSI'!$I$10:$I$1000,'TRANSAKSI'!$E$10:$E$1000,"4.1.14.01",'TRANSAKSI'!$J$10:$J$1000,6,'TRANSAKSI'!$K$10:$K$1000,TahunSel)-SUMIFS('TRANSAKSI'!$H$10:$H$1000,'TRANSAKSI'!$E$10:$E$1000,"4.1.14.01",'TRANSAKSI'!$J$10:$J$1000,6,'TRANSAKSI'!$K$10:$K$1000,TahunSel) | J20: =SUMIFS('TRANSAKSI'!$I$10:$I$1000,'TRANSAKSI'!$E$10:$E$1000,"4.1.14.01",'TRANSAKSI'!$J$10:$J$1000,7,'TRANSAKSI'!$K$10:$K$1000,TahunSel)-SUMIFS('TRANSAKSI'!$H$10:$H$1000,'TRANSAKSI'!$E$10:$E$1000,"4.1.14.01",'TRANSAKSI'!$J$10:$J$1000,7,'TRANSAKSI'!$K$10:$K$1000,TahunSel) | K20: =SUMIFS('TRANSAKSI'!$I$10:$I$1000,'TRANSAKSI'!$E$10:$E$1000,"4.1.14.01",'TRANSAKSI'!$J$10:$J$1000,8,'TRANSAKSI'!$K$10:$K$1000,TahunSel)-SUMIFS('TRANSAKSI'!$H$10:$H$1000,'TRANSAKSI'!$E$10:$E$1000,"4.1.14.01",'TRANSAKSI'!$J$10:$J$1000,8,'TRANSAKSI'!$K$10:$K$1000,TahunSel) | L20: =SUMIFS('TRANSAKSI'!$I$10:$I$1000,'TRANSAKSI'!$E$10:$E$1000,"4.1.14.01",'TRANSAKSI'!$J$10:$J$1000,9,'TRANSAKSI'!$K$10:$K$1000,TahunSel)-SUMIFS('TRANSAKSI'!$H$10:$H$1000,'TRANSAKSI'!$E$10:$E$1000,"4.1.14.01",'TRANSAKSI'!$J$10:$J$1000,9,'TRANSAKSI'!$K$10:$K$1000,TahunSel) | M20: =SUMIFS('TRANSAKSI'!$I$10:$I$1000,'TRANSAKSI'!$E$10:$E$1000,"4.1.14.01",'TRANSAKSI'!$J$10:$J$1000,10,'TRANSAKSI'!$K$10:$K$1000,TahunSel)-SUMIFS('TRANSAKSI'!$H$10:$H$1000,'TRANSAKSI'!$E$10:$E$1000,"4.1.14.01",'TRANSAKSI'!$J$10:$J$1000,10,'TRANSAKSI'!$K$10:$K$1000,TahunSel) | N20: =SUMIFS('TRANSAKSI'!$I$10:$I$1000,'TRANSAKSI'!$E$10:$E$1000,"4.1.14.01",'TRANSAKSI'!$J$10:$J$1000,11,'TRANSAKSI'!$K$10:$K$1000,TahunSel)-SUMIFS('TRANSAKSI'!$H$10:$H$1000,'TRANSAKSI'!$E$10:$E$1000,"4.1.14.01",'TRANSAKSI'!$J$10:$J$1000,11,'TRANSAKSI'!$K$10:$K$1000,TahunSel) | O20: =SUMIFS('TRANSAKSI'!$I$10:$I$1000,'TRANSAKSI'!$E$10:$E$1000,"4.1.14.01",'TRANSAKSI'!$J$10:$J$1000,12,'TRANSAKSI'!$K$10:$K$1000,TahunSel)-SUMIFS('TRANSAKSI'!$H$10:$H$1000,'TRANSAKSI'!$E$10:$E$1000,"4.1.14.01",'TRANSAKSI'!$J$10:$J$1000,12,'TRANSAKSI'!$K$10:$K$1000,TahunSel) | P20: =SUM(D20:O20)
B21: Total Pendapatan | D21: =SUM(D8:D20) | E21: =SUM(E8:E20) | F21: =SUM(F8:F20) | G21: =SUM(G8:G20) | H21: =SUM(H8:H20) | I21: =SUM(I8:I20) | J21: =SUM(J8:J20) | K21: =SUM(K8:K20) | ... P21: =SUM(P8:P20)
A23: BEBAN
A24: 6.1.02.01 | B24: Beban Alat Tulis Kantor (ATK) | C24: Beban | D24: =SUMIFS('TRANSAKSI'!$H$10:$H$1000,'TRANSAKSI'!$E$10:$E$1000,"6.1.02.01",'TRANSAKSI'!$J$10:$J$1000,1,'TRANSAKSI'!$K$10:$K$1000,TahunSel)-SUMIFS('TRANSAKSI'!$I$10:$I$1000,'TRANSAKSI'!$E$10:$E$1000,"6.1.02.01",'TRANSAKSI'!$J$10:$J$1000,1,'TRANSAKSI'!$K$10:$K$1000,TahunSel) | E24: =SUMIFS('TRANSAKSI'!$H$10:$H$1000,'TRANSAKSI'!$E$10:$E$1000,"6.1.02.01",'TRANSAKSI'!$J$10:$J$1000,2,'TRANSAKSI'!$K$10:$K$1000,TahunSel)-SUMIFS('TRANSAKSI'!$I$10:$I$1000,'TRANSAKSI'!$E$10:$E$1000,"6.1.02.01",'TRANSAKSI'!$J$10:$J$1000,2,'TRANSAKSI'!$K$10:$K$1000,TahunSel) | F24: =SUMIFS('TRANSAKSI'!$H$10:$H$1000,'TRANSAKSI'!$E$10:$E$1000,"6.1.02.01",'TRANSAKSI'!$J$10:$J$1000,3,'TRANSAKSI'!$K$10:$K$1000,TahunSel)-SUMIFS('TRANSAKSI'!$I$10:$I$1000,'TRANSAKSI'!$E$10:$E$1000,"6.1.02.01",'TRANSAKSI'!$J$10:$J$1000,3,'TRANSAKSI'!$K$10:$K$1000,TahunSel) | G24: =SUMIFS('TRANSAKSI'!$H$10:$H$1000,'TRANSAKSI'!$E$10:$E$1000,"6.1.02.01",'TRANSAKSI'!$J$10:$J$1000,4,'TRANSAKSI'!$K$10:$K$1000,TahunSel)-SUMIFS('TRANSAKSI'!$I$10:$I$1000,'TRANSAKSI'!$E$10:$E$1000,"6.1.02.01",'TRANSAKSI'!$J$10:$J$1000,4,'TRANSAKSI'!$K$10:$K$1000,TahunSel) | H24: =SUMIFS('TRANSAKSI'!$H$10:$H$1000,'TRANSAKSI'!$E$10:$E$1000,"6.1.02.01",'TRANSAKSI'!$J$10:$J$1000,5,'TRANSAKSI'!$K$10:$K$1000,TahunSel)-SUMIFS('TRANSAKSI'!$I$10:$I$1000,'TRANSAKSI'!$E$10:$E$1000,"6.1.02.01",'TRANSAKSI'!$J$10:$J$1000,5,'TRANSAKSI'!$K$10:$K$1000,TahunSel) | I24: =SUMIFS('TRANSAKSI'!$H$10:$H$1000,'TRANSAKSI'!$E$10:$E$1000,"6.1.02.01",'TRANSAKSI'!$J$10:$J$1000,6,'TRANSAKSI'!$K$10:$K$1000,TahunSel)-SUMIFS('TRANSAKSI'!$I$10:$I$1000,'TRANSAKSI'!$E$10:$E$1000,"6.1.02.01",'TRANSAKSI'!$J$10:$J$1000,6,'TRANSAKSI'!$K$10:$K$1000,TahunSel) | J24: =SUMIFS('TRANSAKSI'!$H$10:$H$1000,'TRANSAKSI'!$E$10:$E$1000,"6.1.02.01",'TRANSAKSI'!$J$10:$J$1000,7,'TRANSAKSI'!$K$10:$K$1000,TahunSel)-SUMIFS('TRANSAKSI'!$I$10:$I$1000,'TRANSAKSI'!$E$10:$E$1000,"6.1.02.01",'TRANSAKSI'!$J$10:$J$1000,7,'TRANSAKSI'!$K$10:$K$1000,TahunSel) | K24: =SUMIFS('TRANSAKSI'!$H$10:$H$1000,'TRANSAKSI'!$E$10:$E$1000,"6.1.02.01",'TRANSAKSI'!$J$10:$J$1000,8,'TRANSAKSI'!$K$10:$K$1000,TahunSel)-SUMIFS('TRANSAKSI'!$I$10:$I$1000,'TRANSAKSI'!$E$10:$E$1000,"6.1.02.01",'TRANSAKSI'!$J$10:$J$1000,8,'TRANSAKSI'!$K$10:$K$1000,TahunSel) | L24: =SUMIFS('TRANSAKSI'!$H$10:$H$1000,'TRANSAKSI'!$E$10:$E$1000,"6.1.02.01",'TRANSAKSI'!$J$10:$J$1000,9,'TRANSAKSI'!$K$10:$K$1000,TahunSel)-SUMIFS('TRANSAKSI'!$I$10:$I$1000,'TRANSAKSI'!$E$10:$E$1000,"6.1.02.01",'TRANSAKSI'!$J$10:$J$1000,9,'TRANSAKSI'!$K$10:$K$1000,TahunSel) | M24: =SUMIFS('TRANSAKSI'!$H$10:$H$1000,'TRANSAKSI'!$E$10:$E$1000,"6.1.02.01",'TRANSAKSI'!$J$10:$J$1000,10,'TRANSAKSI'!$K$10:$K$1000,TahunSel)-SUMIFS('TRANSAKSI'!$I$10:$I$1000,'TRANSAKSI'!$E$10:$E$1000,"6.1.02.01",'TRANSAKSI'!$J$10:$J$1000,10,'TRANSAKSI'!$K$10:$K$1000,TahunSel) | N24: =SUMIFS('TRANSAKSI'!$H$10:$H$1000,'TRANSAKSI'!$E$10:$E$1000,"6.1.02.01",'TRANSAKSI'!$J$10:$J$1000,11,'TRANSAKSI'!$K$10:$K$1000,TahunSel)-SUMIFS('TRANSAKSI'!$I$10:$I$1000,'TRANSAKSI'!$E$10:$E$1000,"6.1.02.01",'TRANSAKSI'!$J$10:$J$1000,11,'TRANSAKSI'!$K$10:$K$1000,TahunSel) | O24: =SUMIFS('TRANSAKSI'!$H$10:$H$1000,'TRANSAKSI'!$E$10:$E$1000,"6.1.02.01",'TRANSAKSI'!$J$10:$J$1000,12,'TRANSAKSI'!$K$10:$K$1000,TahunSel)-SUMIFS('TRANSAKSI'!$I$10:$I$1000,'TRANSAKSI'!$E$10:$E$1000,"6.1.02.01",'TRANSAKSI'!$J$10:$J$1000,12,'TRANSAKSI'!$K$10:$K$1000,TahunSel) | P24: =SUM(D24:O24)
